Workbook

Sheet 2017 Stats
A1: Rk | B1: Player | C1: Tm | D1: FantPos | E1: Age | F1: Games G | G1: Games GS | H1: Passing Cmp | I1: Passing Att | J1: Passing Yds | K1: Passing TD | L1: Passing Int | M1: Rushing Att | N1: Rushing Yds | O1: Rushing Y/A | P1: Rushing TD | Q1: Receiving Tgt | R1: Receiving Rec | S1: Receiving Yds | T1: Receiving Y/R | U1: Receiving TD | V1: Fumbles Fmb | W1: Fumbles FL | X1: Scoring TD | Y1: Scoring 2PM | Z1: Scoring 2PP | AA1: Fantasy FantPt | AB1: Fantasy PPR | AC1: Fantasy DKPt | AD1: Fantasy FDPt | AE1: Fantasy VBD | AF1: Fantasy PosRank | AG1: Fantasy OvRank | AH1: Custom
A2: 1 | B2: Todd Gurley | C2: LAR | D2: RB | E2: 23 | F2: 15 | G2: 15 | H2: 0 | I2: 0 | J2: 0 | K2: 0 | L2: 0 | M2: 279 | N2: 1305 | O2: 4.68 | P2: 13 | Q2: 87 | R2: 64 | S2: 788 | T2: 12.31 | U2: 6 | V2: 5 | W2: 2 | X2: 19 | Y2: 0 | Z2: 0 | AA2: 319 | AB2: 383.3 | AC2: 391.3 | AD2: 351.3 | AE2: 192 | AF2: 1 | AG2: 1 | AH2: N
A3: 2 | B3: Le'Veon Bell | C3: PIT | D3: RB | E3: 25 | F3: 15 | G3: 15 | H3: 0 | I3: 0 | J3: 0 | K3: 0 | L3: 0 | M3: 321 | N3: 1291 | O3: 4.02 | P3: 9 | Q3: 106 | R3: 85 | S3: 655 | T3: 7.71 | U3: 2 | V3: 3 | W3: 2 | X3: 11 | Y3: 0 | Z3: 0 | AA3: 257 | AB3: 341.6 | AC3: 349.6 | AD3: 299.1 | AE3: 130 | AF3: 2 | AG3: 2 | AH3: N
A4: 3 | B4: Kareem Hunt | C4: KAN | D4: RB | E4: 22 | F4: 16 | G4: 16 | H4: 0 | I4: 0 | J4: 0 | K4: 0 | L4: 0 | M4: 272 | N4: 1327 | O4: 4.88 | P4: 8 | Q4: 63 | R4: 53 | S4: 455 | T4: 8.58 | U4: 3 | V4: 1 | W4: 1 | X4: 11 | Y4: 0 | Z4: 0 | AA4: 242 | AB4: 295.2 | AC4: 302.2 | AD4: 268.7 | AE4: 115 | AF4: 3 | AG4: 3 | AH4: N
A5: 4 | B5: Alvin Kamara | C5: NOR | D5: RB | E5: 22 | F5: 16 | G5: 3 | H5: 0 | I5: 0 | J5: 0 | K5: 0 | L5: 0 | M5: 120 | N5: 728 | O5: 6.07 | P5: 8 | Q5: 100 | R5: 81 | S5: 826 | T5: 10.2 | U5: 5 | V5: 1 | W5: 1 | X5: 14 | Y5: 1 | Z5: 0 | AA5: 239 | AB5: 320.4 | AC5: 327.4 | AD5: 279.9 | AE5: 112 | AF5: 4 | AG5: 4 | AH5: N
A6: 5 | B6: Melvin Gordon | C6: LAC | D6: RB | E6: 24 | F6: 16 | G6: 16 | H6: 0 | I6: 0 | J6: 0 | K6: 0 | L6: 0 | M6: 284 | N6: 1105 | O6: 3.89 | P6: 8 | Q6: 83 | R6: 58 | S6: 476 | T6: 8.21 | U6: 4 | V6: 1 | W6: 0 | X6: 12 | Y6: 0 | Z6: 0 | AA6: 230 | AB6: 288.1 | AC6: 294.1 | AD6: 259.1 | AE6: 103 | AF6: 5 | AG6: 5 | AH6: N
A7: 6 | B7: DeAndre Hopkins | C7: HOU | D7: WR | E7: 25 | F7: 15 | G7: 15 | H7: 0 | I7: 0 | J7: 0 | K7: 0 | L7: 0 | M7: 0 | N7: 0 | O7: 0 | P7: 0 | Q7: 174 | R7: 96 | S7: 1378 | T7: 14.35 | U7: 13 | V7: 1 | W7: 1 | X7: 13 | Y7: 0 | Z7: 0 | AA7: 214 | AB7: 309.8 | AC7: 313.8 | AD7: 261.8 | AE7: 103 | AF7: 1 | AG7: 6 | AH7: N
A8: 7 | B8: Antonio Brown | C8: PIT | D8: WR | E8: 29 | F8: 14 | G8: 14 | H8: 0 | I8: 0 | J8: 0 | K8: 0 | L8: 0 | M8: 0 | N8: 0 | O8: 0 | P8: 0 | Q8: 163 | R8: 101 | S8: 1533 | T8: 15.18 | U8: 9 | V8: 4 | W8: 0 | X8: 9 | Y8: 1 | Z8: 0 | AA8: 209 | AB8: 310.3 | AC8: 313.3 | AD8: 259.8 | AE8: 98 | AF8: 2 | AG8: 7 | AH8: N
A9: 8 | B9: Mark Ingram | C9: NOR | D9: RB | E9: 28 | F9: 16 | G9: 12 | H9: 0 | I9: 0 | J9: 0 | K9: 0 | L9: 0 | M9: 230 | N9: 1124 | O9: 4.89 | P9: 12 | Q9: 71 | R9: 58 | S9: 416 | T9: 7.17 | U9: 0 | V9: 3 | W9: 3 | X9: 12 | Y9: 0 | Z9: 0 | AA9: 220 | AB9: 278 | AC9: 287 | AD9: 249 | AE9: 93 | AF9: 6 | AG9: 8 | AH9: N
A10: 9 | B10: Russell Wilson | C10: SEA | D10: QB | E10: 29 | F10: 16 | G10: 16 | H10: 339 | I10: 553 | J10: 3983 | K10: 34 | L10: 11 | M10: 95 | N10: 586 | O10: 6.17 | P10: 3 | Q10: 0 | R10: 0 | S10: 0 | T10: 0 | U10: 0 | V10: 14 | W10: 3 | X10: 3 | Y10: 0 | Z10: 2 | AA10: 348 | AB10: 347.9 | AC10: 367.9 | AD10: 358.9 | AE10: 93 | AF10: 1 | AG10: 9 | AH10: N
A11: 10 | B11: LeSean McCoy | C11: BUF | D11: RB | E11: 29 | F11: 16 | G11: 16 | H11: 0 | I11: 0 | J11: 0 | K11: 0 | L11: 0 | M11: 287 | N11: 1138 | O11: 3.97 | P11: 6 | Q11: 77 | R11: 59 | S11: 448 | T11: 7.59 | U11: 2 | V11: 3 | W11: 1 | X11: 8 | Y11: 0 | Z11: 0 | AA11: 205 | AB11: 263.6 | AC11: 270.6 | AD11: 234.1 | AE11: 78 | AF11: 7 | AG11: 10 | AH11: N
A12: 11 | B12: Rob Gronkowski | C12: NWE | D12: TE | E12: 28 | F12: 14 | G12: 14 | H12: 0 | I12: 0 | J12: 0 | K12: 0 | L12: 0 | M12: 0 | N12: 0 | O12: 0 | P12: 0 | Q12: 105 | R12: 69 | S12: 1084 | T12: 15.71 | U12: 8 | V12: 1 | W12: 0 | X12: 8 | Y12: 1 | Z12: 0 | AA12: 158 | AB12: 227.4 | AC12: 230.4 | AD12: 192.9 | AE12: 77 | AF12: 1 | AG12: 11 | AH12: N
A13: 12 | B13: Travis Kelce | C13: KAN | D13: TE | E13: 28 | F13: 15 | G13: 15 | H13: 0 | I13: 1 | J13: 0 | K13: 0 | L13: 1 | M13: 2 | N13: 7 | O13: 3.5 | P13: 0 | Q13: 122 | R13: 83 | S13: 1038 | T13: 12.51 | U13: 8 | V13: 0 | W13: 0 | X13: 8 | Y13: 0 | Z13: 0 | AA13: 151 | AB13: 233.5 | AC13: 237.5 | AD13: 193 | AE13: 69 | AF13: 2 | AG13: 12 | AH13: N
... A75: 74 | B75: Tyler Kroft | C75: CIN | D75: TE | E75: 25 | F75: 16 | G75: 16 | H75: 0 | I75: 0 | J75: 0 | K75: 0 | L75: 0 | M75: 0 | N75: 0 | O75: 0 | P75: 0 | Q75: 62 | R75: 42 | S75: 404 | T75: 9.62 | U75: 7 | V75: 0 | W75: 0 | X75: 7 | Y75: 0 | Z75: 0 | AA75: 82 | AB75: 124.4 | AC75: 127.4 | AD75: 103.4 | AE75: 1 | AF75: 11 | AG75: 74 | AH75: N
A76: 75 | B76: Jermaine Kearse | C76: NYJ | D76: WR | E76: 27 | F76: 16 | G76: 14 | H76: 0 | I76: 0 | J76: 0 | K76: 0 | L76: 0 | M76: 0 | N76: 0 | O76: 0 | P76: 0 | Q76: 102 | R76: 65 | S76: 810 | T76: 12.46 | U76: 5 | V76: 1 | W76: 0 | X76: 5 | Y76: 0 | Z76: 0 | AA76: 111 | AB76: 176 | AC76: 179 | AD76: 143.5 | AF76: 30 | AG76: 75 | AH76: N
A77: 76 | B77: Jared Goff | C77: LAR | D77: QB | E77: 23 | F77: 15 | G77: 15 | H77: 296 | I77: 477 | J77: 3804 | K77: 28 | L77: 7 | M77: 28 | N77: 51 | O77: 1.82 | P77: 1 | Q77: 0 | R77: 0 | S77: 0 | T77: 0 | U77: 0 | V77: 8 | W77: 3 | X77: 1 | Y77: 0 | Z77: 0 | AA77: 255 | AB77: 255.3 | AC77: 268.3 | AD77: 262.3 | AF77: 12 | AG77: 76 | AH77: N
A78: 77 | B78: Hunter Henry | C78: LAC | D78: TE | E78: 23 | F78: 14 | G78: 13 | H78: 0 | I78: 0 | J78: 0 | K78: 0 | L78: 0 | M78: 0 | N78: 0 | O78: 0 | P78: 0 | Q78: 62 | R78: 45 | S78: 579 | T78: 12.87 | U78: 4 | V78: 0 | W78: 0 | X78: 4 | Y78: 0 | Z78: 0 | AA78: 82 | AB78: 126.9 | AC78: 129.9 | AD78: 104.4 | AF78: 12 | AG78: 77 | AH78: N
A79: 78 | B79: Alex Armah | C79: CAR | E79: 23 | F79: 9 | G79: 0 | H79: 0 | I79: 0 | J79: 0 | K79: 0 | L79: 0 | M79: 0 | N79: 0 | O79: 0 | P79: 0 | Q79: 0 | R79: 0 | S79: 0 | T79: 0 | U79: 0 | V79: 0 | W79: 0 | X79: 0 | Y79: 0 | Z79: 0 | AF79: 1 | AG79: 78 | AH79: N
A80: 79 | B80: Blake Bortles | C80: JAX | D80: QB | E80: 25 | F80: 16 | G80: 16 | H80: 315 | I80: 523 | J80: 3687 | K80: 21 | L80: 13 | M80: 57 | N80: 322 | O80: 5.65 | P80: 2 | Q80: 0 | R80: 0 | S80: 0 | T80: 0 | U80: 0 | V80: 9 | W80: 3 | X80: 2 | Y80: 0 | Z80: 3 | AA80: 250 | AB80: 249.7 | AC80: 271.7 | AD80: 262.7 | AF80: 13 | AH80: N
A81: 80 | B81: Case Keenum | C81: MIN | D81: QB | E81: 29 | F81: 15 | G81: 14 | H81: 325 | I81: 481 | J81: 3547 | K81: 22 | L81: 7 | M81: 40 | N81: 160 | O81: 4 | P81: 1 | Q81: 0 | R81: 0 | S81: 0 | T81: 0 | U81: 0 | V81: 1 | W81: 1 | X81: 1 | Y81: 0 | Z81: 1 | AA81: 238 | AB81: 237.9 | AC81: 251.9 | AD81: 244.9 | AF81: 14 | AH81: N
A82: 81 | B82: Matt Ryan | C82: ATL | D82: QB | E82: 32 | F82: 16 | G82: 16 | H82: 342 | I82: 529 | J82: 4095 | K82: 20 | L82: 12 | M82: 32 | N82: 143 | O82: 4.47 | P82: 0 | Q82: 0 | R82: 0 | S82: 0 | T82: 0 | U82: 0 | V82: 4 | W82: 3 | X82: 0 | Y82: 0 | Z82: 0 | AA82: 228 | AB82: 228.1 | AC82: 249.1 | AD82: 240.1 | AF82: 15 | AH82: N
A83: 82 | B83: Tyrod Taylor | C83: BUF | D83: QB | E83: 28 | F83: 15 | G83: 14 | H83: 263 | I83: 420 | J83: 2799 | K83: 14 | L83: 4 | M83: 84 | N83: 427 | O83: 5.08 | P83: 4 | Q83: 0 | R83: 0 | S83: 0 | T83: 0 | U83: 0 | V83: 4 | W83: 2 | X83: 4 | Y83: 0 | Z83: 0 | AA83: 223 | AB83: 222.7 | AC83: 234.7 | AD83: 226.7 | AF83: 16 | AH83: N
A84: 83 | B84: Andy Dalton | C84: CIN | D84: QB | E84: 30 | F84: 16 | G84: 16 | H84: 297 | I84: 496 | J84: 3320 | K84: 25 | L84: 12 | M84: 38 | N84: 99 | O84: 2.61 | P84: 0 | Q84: 0 | R84: 0 | S84: 0 | T84: 0 | U84: 0 | V84: 4 | W84: 4 | X84: 0 | Y84: 0 | Z84: 0 | AA84: 211 | AB84: 210.7 | AC84: 229.7 | AD84: 222.7 | AF84: 17 | AH84: N
A85: 84 | B85: Marcus Mariota | C85: TEN | D85: QB | E85: 24 | F85: 15 | G85: 15 | H85: 281 | I85: 453 | J85: 3232 | K85: 13 | L85: 15 | M85: 60 | N85: 312 | O85: 5.2 | P85: 5 | Q85: 0 | R85: 0 | S85: 0 | T85: 0 | U85: 0 | V85: 2 | W85: 1 | X85: 5 | Y85: 0 | Z85: 0 | AA85: 210 | AB85: 210.5 | AC85: 232.5 | AD85: 225.5 | AF85: 18 | AH85: N
A86: 85 | B86: Jacoby Brissett | C86: IND | D86: QB | E86: 25 | F86: 16 | G86: 15 | H86: 276 | I86: 469 | J86: 3098 | K86: 13 | L86: 7 | M86: 63 | N86: 260 | O86: 4.13 | P86: 4 | Q86: 0 | R86: 0 | S86: 0 | T86: 0 | U86: 0 | V86: 8 | W86: 3 | X86: 4 | Y86: 0 | Z86: 0 | AA86: 206 | AB86: 205.9 | AC86: 221.9 | AD86: 212.9 | AF86: 20 | AH86: N
A87: 86 | B87: Derek Carr | C87: OAK | D87: QB | E87: 26 | F87: 15 | G87: 15 | H87: 323 | I87: 515 | J87: 3496 | K87: 22 | L87: 13 | M87: 23 | N87: 66 | O87: 2.87 | P87: 0 | Q87: 0 | R87: 0 | S87: 0 | T87: 0 | U87: 0 | V87: 8 | W87: 3 | X87: 0 | Y87: 0 | Z87: 2 | AA87: 206 | AB87: 206.4 | AC87: 225.4 | AD87: 219.4 | AF87: 19 | AH87: N
A88: 87 | B88: Josh McCown | C88: NYJ | D88: QB | E88: 38 | F88: 13 | G88: 13 | H88: 267 | I88: 397 | J88: 2926 | K88: 18 | L88: 9 | M88: 37 | N88: 124 | O88: 3.35 | P88: 5 | Q88: 0 | R88: 0 | S88: 0 | T88: 0 | U88: 0 | V88: 11 | W88: 4 | X88: 5 | Y88: 0 | Z88: 0 | AA88: 205 | AB88: 205.4 | AC88: 224.4 | AD88: 214.4 | AF88: 21 | AH88: N
A89: 88 | B89: Jameis Winston | C89: TAM | D89: QB | E89: 23 | F89: 13 | G89: 13 | H89: 282 | I89: 442 | J89: 3504 | K89: 19 | L89: 11 | M89: 33 | N89: 135 | O89: 4.09 | P89: 1 | Q89: 0 | R89: 0 | S89: 0 | T89: 0 | U89: 0 | V89: 15 | W89: 7 | X89: 1 | Y89: 0 | Z89: 1 | AA89: 202 | AB89: 201.7 | AC89: 225.7 | AD89: 212.7 | AF89: 22 | AH89: N
A90: 89 | B90: Eli Manning | C90: NYG | D90: QB | E90: 36 | F90: 15 | G90: 15 | H90: 352 | I90: 571 | J90: 3468 | K90: 19 | L90: 13 | M90: 12 | N90: 26 | O90: 2.17 | P90: 1 | Q90: 0 | R90: 0 | S90: 0 | T90: 0 | U90: 0 | V90: 11 | W90: 5 | X90: 1 | Y90: 0 | Z90: 0 | AA90: 187 | AB90: 187.3 | AC90: 208.3 | AD90: 200.3 | AF90: 23 | AH90: N
A91: 90 | B91: Joe Flacco | C91: BAL | D91: QB | E91: 32 | F91: 16 | G91: 16 | H91: 352 | I91: 549 | J91: 3141 | K91: 18 | L91: 13 | M91: 25 | N91: 54 | O91: 2.16 | P91: 1 | Q91: 0 | R91: 0 | S91: 0 | T91: 0 | U91: 0 | V91: 6 | W91: 0 | X91: 1 | Y91: 0 | Z91: 1 | AA91: 185 | AB91: 185 | AC91: 201 | AD91: 198 | AF91: 24 | AH91: N
... A516: 515 | B516: Kevin White | C516: CHI | D516: WR | E516: 25 | F516: 1 | G516: 1 | H516: 0 | I516: 0 | J516: 0 | K516: 0 | L516: 0 | M516: 0 | N516: 0 | O516: 0 | P516: 0 | Q516: 4 | R516: 2 | S516: 6 | T516: 3 | U516: 0 | V516: 0 | W516: 0 | X516: 0 | Y516: 0 | Z516: 0 | AA516: 1 | AB516: 2.6 | AC516: 2.6 | AD516: 1.6 | AF516: 192 | AH516: N
A517: 516 | B517: Derek Anderson | C517: CAR | D517: QB | E517: 34 | F517: 3 | G517: 0 | H517: 2 | I517: 8 | J517: 17 | K517: 0 | L517: 0 | M517: 2 | N517: -2 | O517: -1 | P517: 0 | Q517: 0 | R517: 0 | S517: 0 | T517: 0 | U517: 0 | V517: 0 | W517: 0 | X517: 0 | Y517: 0 | Z517: 0 | AB517: 0.5 | AC517: 0.5 | AD517: 0.5 | AF517: 65 | AH517: N
A518: 517 | B518: Joe Banyard | C518: BUF | E518: 29 | F518: 3 | G518: 0 | H518: 0 | I518: 0 | J518: 0 | K518: 0 | L518: 0 | M518: 0 | N518: 0 | O518: 0 | P518: 0 | Q518: 0 | R518: 0 | S518: 0 | T518: 0 | U518: 0 | V518: 0 | W518: 0 | X518: 0 | Y518: 0 | Z518: 0 | AF518: 156 | AH518: N
A519: 518 | B519: Evan Baylis | C519: HOU | E519: 24 | F519: 1 | G519: 0 | H519: 0 | I519: 0 | J519: 0 | K519: 0 | L519: 0 | M519: 0 | N519: 0 | O519: 0 | P519: 0 | Q519: 0 | R519: 0 | S519: 0 | T519: 0 | U519: 0 | V519: 0 | W519: 0 | X519: 0 | Y519: 0 | Z519: 0 | AF519: 122 | AH519: N
A520: 519 | B520: Victor Bolden | C520: SFO | E520: 22 | F520: 9 | G520: 0 | H520: 0 | I520: 0 | J520: 0 | K520: 0 | L520: 0 | M520: 0 | N520: 0 | O520: 0 | P520: 0 | Q520: 0 | R520: 0 | S520: 0 | T520: 0 | U520: 0 | V520: 0 | W520: 0 | X520: 0 | Y520: 0 | Z520: 0 | AF520: 203 | AH520: N
A521: 520 | B521: Ben Braunecker | C521: CHI | E521: 23 | F521: 8 | G521: 0 | H521: 0 | I521: 0 | J521: 0 | K521: 0 | L521: 0 | M521: 0 | N521: 0 | O521: 0 | P521: 0 | Q521: 0 | R521: 0 | S521: 0 | T521: 0 | U521: 0 | V521: 0 | W521: 0 | X521: 0 | Y521: 0 | Z521: 0 | AF521: 109 | AH521: N
A522: 521 | B522: Joe Callahan | C522: GNB | D522: QB | E522: 24 | F522: 1 | G522: 0 | H522: 5 | I522: 7 | J522: 11 | K522: 0 | L522: 0 | M522: 0 | N522: 0 | O522: 0 | P522: 0 | Q522: 0 | R522: 0 | S522: 0 | T522: 0 | U522: 0 | V522: 0 | W522: 0 | X522: 0 | Y522: 0 | Z522: 0 | AB522: 0.4 | AC522: 0.4 | AD522: 0.4 | AF522: 66 | AH522: N
A523: 522 | B523: Cethan Carter | C523: CIN | E523: 22 | F523: 16 | G523: 0 | H523: 0 | I523: 0 | J523: 0 | K523: 0 | L523: 0 | M523: 0 | N523: 0 | O523: 0 | P523: 0 | Q523: 0 | R523: 0 | S523: 0 | T523: 0 | U523: 0 | V523: 0 | W523: 0 | X523: 0 | Y523: 0 | Z523: 0 | AF523: 111 | AH523: N
A524: 523 | B524: Stacy Coley | C524: MIN | E524: 23 | F524: 4 | G524: 0 | H524: 0 | I524: 0 | J524: 0 | K524: 0 | L524: 0 | M524: 0 | N524: 0 | O524: 0 | P524: 0 | Q524: 0 | R524: 0 | S524: 0 | T524: 0 | U524: 0 | V524: 0 | W524: 0 | X524: 0 | Y524: 0 | Z524: 0 | AF524: 204 | AH524: N
A525: 524 | B525: Cody Core | C525: CIN | E525: 23 | F525: 13 | G525: 0 | H525: 0 | I525: 0 | J525: 0 | K525: 0 | L525: 0 | M525: 0 | N525: 0 | O525: 0 | P525: 0 | Q525: 4 | R525: 0 | S525: 0 | T525: 0 | U525: 0 | V525: 0 | W525: 0 | X525: 0 | Y525: 0 | Z525: 0 | AF525: 199 | AH525: N
...

Sheet 2018 Stats
A1: Rk | B1: Player | C1: Tm | D1: FantPos | E1: Age | F1: Games G | G1: Games GS | H1: Passing Cmp | I1: Passing Att | J1: Passing Yds | K1: Passing TD | L1: Passing Int | M1: Rushing Att | N1: Rushing Yds | O1: Rushing Y/A | P1: Rushing TD | Q1: Receiving Tgt | R1: Receiving Rec | S1: Receiving Yds | T1: Receiving Y/R | U1: Receiving TD | V1: Fumbles Fmb | W1: Fumbles FL | X1: Scoring TD | Y1: Scoring 2PM | Z1: Scoring 2PP | AA1: Fantasy FantPt | AB1: Fantasy PPR | AC1: Fantasy DKPt | AD1: Fantasy FDPt | AE1: Fantasy VBD | AF1: Fantasy PosRank | AG1: Fantasy OvRank | AH1: Custom
A2: 1 | B2: Todd Gurley | C2: LAR | D2: RB | E2: 24 | F2: 14 | G2: 14 | H2: 0 | I2: 0 | J2: 0 | K2: 0 | L2: 0 | M2: 256 | N2: 1251 | O2: 4.89 | P2: 17 | Q2: 81 | R2: 59 | S2: 580 | T2: 9.83 | U2: 4 | V2: 1 | W2: 1 | X2: 21 | Y2: 3 | Z2: 0 | AA2: 313 | AB2: 372.1 | AC2: 379.1 | AD2: 342.6 | AE2: 178 | AF2: 1 | AG2: 1 | AH2: N
A3: 2 | B3: Saquon Barkley | C3: NYG | D3: RB | E3: 21 | F3: 16 | G3: 16 | H3: 0 | I3: 0 | J3: 0 | K3: 0 | L3: 0 | M3: 261 | N3: 1307 | O3: 5.01 | P3: 11 | Q3: 121 | R3: 91 | S3: 721 | T3: 7.92 | U3: 4 | V3: 0 | W3: 0 | X3: 15 | Y3: 1 | Z3: 0 | AA3: 295 | AB3: 385.8 | AC3: 391.8 | AD3: 340.3 | AE3: 159 | AF3: 2 | AG3: 2 | AH3: N
A4: 3 | B4: Christian McCaffrey | C4: CAR | D4: RB | E4: 22 | F4: 16 | G4: 16 | H4: 1 | I4: 1 | J4: 50 | K4: 1 | L4: 0 | M4: 219 | N4: 1098 | O4: 5.01 | P4: 7 | Q4: 124 | R4: 107 | S4: 867 | T4: 8.1 | U4: 6 | V4: 4 | W4: 1 | X4: 13 | Y4: 0 | Z4: 0 | AA4: 279 | AB4: 385.5 | AC4: 392.5 | AD4: 332 | AE4: 143 | AF4: 3 | AG4: 3 | AH4: N
A5: 4 | B5: Alvin Kamara | C5: NOR | D5: RB | E5: 23 | F5: 15 | G5: 13 | H5: 0 | I5: 0 | J5: 0 | K5: 0 | L5: 0 | M5: 194 | N5: 883 | O5: 4.55 | P5: 14 | Q5: 105 | R5: 81 | S5: 709 | T5: 8.75 | U5: 4 | V5: 1 | W5: 0 | X5: 18 | Y5: 3 | Z5: 0 | AA5: 273 | AB5: 354.2 | AC5: 360.2 | AD5: 313.7 | AE5: 138 | AF5: 4 | AG5: 4 | AH5: N
A6: 5 | B6: Patrick Mahomes | C6: KAN | D6: QB | E6: 23 | F6: 16 | G6: 16 | H6: 383 | I6: 580 | J6: 5097 | K6: 50 | L6: 12 | M6: 60 | N6: 272 | O6: 4.53 | P6: 2 | Q6: 0 | R6: 0 | S6: 0 | T6: 0 | U6: 0 | V6: 9 | W6: 2 | X6: 2 | Y6: 1 | Z6: 0 | AA6: 417 | AB6: 417.1 | AC6: 437.1 | AD6: 429.1 | AE6: 134 | AF6: 1 | AG6: 5 | AH6: N
A7: 6 | B7: Tyreek Hill | C7: KAN | D7: WR | E7: 24 | F7: 16 | G7: 16 | H7: 0 | I7: 0 | J7: 0 | K7: 0 | L7: 0 | M7: 22 | N7: 151 | O7: 6.86 | P7: 1 | Q7: 137 | R7: 87 | S7: 1479 | T7: 17 | U7: 12 | V7: 0 | W7: 0 | X7: 14 | Y7: 0 | Z7: 0 | AA7: 247 | AB7: 334 | AC7: 340 | AD7: 290.5 | AE7: 131 | AF7: 1 | AG7: 6 | AH7: N
A8: 7 | B8: Ezekiel Elliott | C8: DAL | D8: RB | E8: 23 | F8: 15 | G8: 15 | H8: 0 | I8: 0 | J8: 0 | K8: 0 | L8: 0 | M8: 304 | N8: 1434 | O8: 4.72 | P8: 6 | Q8: 95 | R8: 77 | S8: 567 | T8: 7.36 | U8: 3 | V8: 6 | W8: 1 | X8: 9 | Y8: 0 | Z8: 0 | AA8: 252 | AB8: 329.1 | AC8: 336.1 | AD8: 290.6 | AE8: 117 | AF8: 5 | AG8: 7 | AH8: N
A9: 8 | B9: Travis Kelce | C9: KAN | D9: TE | E9: 29 | F9: 16 | G9: 16 | H9: 0 | I9: 0 | J9: 0 | K9: 0 | L9: 0 | M9: 0 | N9: 0 | O9: 0 | P9: 0 | Q9: 150 | R9: 103 | S9: 1336 | T9: 12.97 | U9: 10 | V9: 2 | W9: 1 | X9: 10 | Y9: 0 | Z9: 0 | AA9: 192 | AB9: 294.6 | AC9: 298.6 | AD9: 243.1 | AE9: 109 | AF9: 1 | AG9: 8 | AH9: N
A10: 9 | B10: Antonio Brown | C10: PIT | D10: WR | E10: 30 | F10: 15 | G10: 15 | H10: 0 | I10: 1 | J10: 0 | K10: 0 | L10: 0 | M10: 0 | N10: 0 | O10: 0 | P10: 0 | Q10: 168 | R10: 104 | S10: 1297 | T10: 12.47 | U10: 15 | V10: 0 | W10: 0 | X10: 15 | Y10: 0 | Z10: 0 | AA10: 220 | AB10: 323.7 | AC10: 326.7 | AD10: 271.7 | AE10: 103 | AF10: 2 | AG10: 9 | AH10: N
A11: 10 | B11: Davante Adams | C11: GNB | D11: WR | E11: 26 | F11: 15 | G11: 15 | H11: 0 | I11: 0 | J11: 0 | K11: 0 | L11: 0 | M11: 0 | N11: 0 | O11: 0 | P11: 0 | Q11: 169 | R11: 111 | S11: 1386 | T11: 12.49 | U11: 13 | V11: 0 | W11: 0 | X11: 13 | Y11: 1 | Z11: 0 | AA11: 219 | AB11: 329.6 | AC11: 332.6 | AD11: 274.1 | AE11: 102 | AF11: 3 | AG11: 10 | AH11: N
A12: 11 | B12: DeAndre Hopkins | C12: HOU | D12: WR | E12: 26 | F12: 16 | G12: 16 | H12: 0 | I12: 1 | J12: 0 | K12: 0 | L12: 0 | M12: 1 | N12: -7 | O12: -7 | P12: 0 | Q12: 163 | R12: 115 | S12: 1572 | T12: 13.67 | U12: 11 | V12: 2 | W12: 2 | X12: 11 | Y12: 0 | Z12: 0 | AA12: 219 | AB12: 333.5 | AC12: 338.5 | AD12: 276 | AE12: 102 | AF12: 4 | AG12: 11 | AH12: N
A13: 12 | B13: Julio Jones | C13: ATL | D13: WR | E13: 29 | F13: 16 | G13: 16 | H13: 0 | I13: 0 | J13: 0 | K13: 0 | L13: 0 | M13: 2 | N13: 12 | O13: 6 | P13: 0 | Q13: 170 | R13: 113 | S13: 1677 | T13: 14.84 | U13: 8 | V13: 2 | W13: 2 | X13: 8 | Y13: 0 | Z13: 0 | AA13: 213 | AB13: 325.9 | AC13: 330.9 | AD13: 269.4 | AE13: 97 | AF13: 5 | AG13: 12 | AH13: N
... A73: 72 | B73: Rob Gronkowski | C73: NWE | D73: TE | E73: 29 | F73: 13 | G73: 11 | H73: 0 | I73: 0 | J73: 0 | K73: 0 | L73: 0 | M73: 0 | N73: 0 | O73: 0 | P73: 0 | Q73: 72 | R73: 47 | S73: 682 | T73: 14.51 | U73: 3 | V73: 1 | W73: 1 | X73: 3 | Y73: 0 | Z73: 0 | AA73: 84 | AB73: 131.2 | AC73: 135.2 | AD73: 107.7 | AE73: 1 | AF73: 11 | AG73: 72 | AH73: N
A74: 73 | B74: Larry Fitzgerald | C74: ARI | D74: WR | E74: 35 | F74: 16 | G74: 16 | H74: 1 | I74: 1 | J74: 32 | K74: 1 | L74: 0 | M74: 0 | N74: 0 | O74: 0 | P74: 0 | Q74: 112 | R74: 69 | S74: 734 | T74: 10.64 | U74: 6 | V74: 0 | W74: 0 | X74: 6 | Y74: 1 | Z74: 0 | AA74: 117 | AB74: 185.7 | AC74: 188.7 | AD74: 151.2 | AF74: 28 | AG74: 73 | AH74: N
A75: 74 | B75: Sterling Shepard | C75: NYG | D75: WR | E75: 25 | F75: 16 | G75: 16 | H75: 0 | I75: 0 | J75: 0 | K75: 0 | L75: 0 | M75: 3 | N75: 33 | O75: 11 | P75: 0 | Q75: 107 | R75: 66 | S75: 872 | T75: 13.21 | U75: 4 | V75: 1 | W75: 0 | X75: 4 | Y75: 1 | Z75: 0 | AA75: 117 | AB75: 182.5 | AC75: 185.5 | AD75: 149.5 | AF75: 29 | AG75: 74 | AH75: N
A76: 75 | B76: Mohamed Sanu | C76: ATL | D76: WR | E76: 29 | F76: 16 | G76: 16 | H76: 1 | I76: 2 | J76: 5 | K76: 1 | L76: 0 | M76: 7 | N76: 44 | O76: 6.29 | P76: 0 | Q76: 94 | R76: 66 | S76: 838 | T76: 12.7 | U76: 4 | V76: 2 | W76: 1 | X76: 4 | Y76: 1 | Z76: 0 | AA76: 116 | AB76: 182.4 | AC76: 186.4 | AD76: 149.4 | AF76: 30 | AG76: 75 | AH76: N
A77: 76 | B77: Matt Breida | C77: SFO | D77: RB | E77: 23 | F77: 14 | G77: 13 | H77: 0 | I77: 0 | J77: 0 | K77: 0 | L77: 0 | M77: 153 | N77: 814 | O77: 5.32 | P77: 3 | Q77: 31 | R77: 27 | S77: 261 | T77: 9.67 | U77: 2 | V77: 1 | W77: 1 | X77: 5 | Y77: 0 | Z77: 0 | AA77: 136 | AB77: 162.5 | AC77: 169.5 | AD77: 149 | AF77: 24 | AG77: 76 | AH77: N
A78: 77 | B78: Shane Smith | C78: NYG | E78: 25 | F78: 2 | G78: 0 | H78: 0 | I78: 0 | J78: 0 | K78: 0 | L78: 0 | M78: 0 | N78: 0 | O78: 0 | P78: 0 | Q78: 0 | R78: 0 | S78: 0 | T78: 0 | U78: 0 | V78: 0 | W78: 0 | X78: 0 | Y78: 0 | Z78: 0 | AF78: 1 | AG78: 77 | AH78: N
A79: 78 | B79: Vance McDonald | C79: PIT | D79: TE | E79: 28 | F79: 15 | G79: 14 | H79: 0 | I79: 0 | J79: 0 | K79: 0 | L79: 0 | M79: 0 | N79: 0 | O79: 0 | P79: 0 | Q79: 72 | R79: 50 | S79: 610 | T79: 12.2 | U79: 4 | V79: 2 | W79: 1 | X79: 4 | Y79: 0 | Z79: 0 | AA79: 83 | AB79: 133 | AC79: 137 | AD79: 108 | AF79: 12 | AG79: 78 | AH79: N
A80: 79 | B80: Cam Newton | C80: CAR | D80: QB | E80: 29 | F80: 14 | G80: 14 | H80: 320 | I80: 471 | J80: 3395 | K80: 24 | L80: 13 | M80: 101 | N80: 488 | O80: 4.83 | P80: 4 | Q80: 0 | R80: 0 | S80: 0 | T80: 0 | U80: 0 | V80: 6 | W80: 0 | X80: 4 | Y80: 0 | Z80: 2 | AA80: 283 | AB80: 282.6 | AC80: 301.6 | AD80: 295.6 | AF80: 12 | AH80: N
A81: 80 | B81: Kirk Cousins | C81: MIN | D81: QB | E81: 30 | F81: 16 | G81: 16 | H81: 425 | I81: 606 | J81: 4298 | K81: 30 | L81: 10 | M81: 44 | N81: 123 | O81: 2.8 | P81: 1 | Q81: 1 | R81: 1 | S81: -1 | T81: -1 | U81: 0 | V81: 9 | W81: 7 | X81: 1 | Y81: 0 | Z81: 3 | AA81: 282 | AB81: 283.1 | AC81: 306.1 | AD81: 292.6 | AF81: 13 | AH81: N
A82: 81 | B82: Tom Brady | C82: NWE | D82: QB | E82: 41 | F82: 16 | G82: 16 | H82: 375 | I82: 570 | J82: 4355 | K82: 29 | L82: 11 | M82: 23 | N82: 35 | O82: 1.52 | P82: 2 | Q82: 1 | R82: 1 | S82: 6 | T82: 6 | U82: 0 | V82: 4 | W82: 2 | X82: 2 | Y82: 0 | Z82: 0 | AA82: 280 | AB82: 281.3 | AC82: 297.3 | AD82: 291.8 | AF82: 14 | AH82: N
A83: 82 | B83: Mitchell Trubisky | C83: CHI | D83: QB | E83: 24 | F83: 14 | G83: 14 | H83: 289 | I83: 434 | J83: 3223 | K83: 24 | L83: 12 | M83: 68 | N83: 421 | O83: 6.19 | P83: 3 | Q83: 0 | R83: 0 | S83: 0 | T83: 0 | U83: 0 | V83: 6 | W83: 3 | X83: 3 | Y83: 0 | Z83: 4 | AA83: 263 | AB83: 263 | AC83: 284 | AD83: 275 | AF83: 15 | AH83: N
A84: 83 | B84: Eli Manning | C84: NYG | D84: QB | E84: 37 | F84: 16 | G84: 16 | H84: 380 | I84: 576 | J84: 4299 | K84: 21 | L84: 11 | M84: 15 | N84: 20 | O84: 1.33 | P84: 1 | Q84: 0 | R84: 0 | S84: 0 | T84: 0 | U84: 0 | V84: 7 | W84: 4 | X84: 1 | Y84: 0 | Z84: 3 | AA84: 240 | AB84: 240 | AC84: 258 | AD84: 251 | AF84: 17 | AH84: N
A85: 84 | B85: Baker Mayfield | C85: CLE | D85: QB | E85: 23 | F85: 14 | G85: 13 | H85: 310 | I85: 486 | J85: 3725 | K85: 27 | L85: 14 | M85: 39 | N85: 131 | O85: 3.36 | P85: 0 | Q85: 1 | R85: 0 | S85: 0 | T85: 0 | U85: 0 | V85: 7 | W85: 3 | X85: 0 | Y85: 1 | Z85: 1 | AA85: 240 | AB85: 240.1 | AC85: 263.1 | AD85: 254.1 | AF85: 16 | AH85: N
A86: 85 | B86: Derek Carr | C86: OAK | D86: QB | E86: 27 | F86: 16 | G86: 16 | H86: 381 | I86: 553 | J86: 4049 | K86: 19 | L86: 10 | M86: 24 | N86: 47 | O86: 1.96 | P86: 1 | Q86: 1 | R86: 1 | S86: -9 | T86: -9 | U86: 0 | V86: 12 | W86: 7 | X86: 1 | Y86: 0 | Z86: 1 | AA86: 216 | AB86: 216.8 | AC86: 236.8 | AD86: 226.3 | AF86: 18 | AH86: N
A87: 86 | B87: Case Keenum | C87: DEN | D87: QB | E87: 30 | F87: 16 | G87: 16 | H87: 365 | I87: 586 | J87: 3890 | K87: 18 | L87: 15 | M87: 26 | N87: 93 | O87: 3.58 | P87: 2 | Q87: 0 | R87: 0 | S87: 0 | T87: 0 | U87: 0 | V87: 11 | W87: 2 | X87: 2 | Y87: 0 | Z87: 0 | AA87: 215 | AB87: 214.9 | AC87: 234.9 | AD87: 229.9 | AF87: 19 | AH87: N
A88: 87 | B88: Matthew Stafford | C88: DET | D88: QB | E88: 30 | F88: 16 | G88: 16 | H88: 367 | I88: 555 | J88: 3777 | K88: 21 | L88: 11 | M88: 25 | N88: 71 | O88: 2.84 | P88: 0 | Q88: 0 | R88: 0 | S88: 0 | T88: 0 | U88: 0 | V88: 6 | W88: 4 | X88: 0 | Y88: 0 | Z88: 0 | AA88: 212 | AB88: 212.2 | AC88: 230.2 | AD88: 223.2 | AF88: 20 | AH88: N
A89: 88 | B89: Josh Allen | C89: BUF | D89: QB | E89: 22 | F89: 12 | G89: 11 | H89: 169 | I89: 320 | J89: 2074 | K89: 10 | L89: 12 | M89: 89 | N89: 631 | O89: 7.09 | P89: 8 | Q89: 1 | R89: 0 | S89: 0 | T89: 0 | U89: 0 | V89: 8 | W89: 2 | X89: 8 | Y89: 0 | Z89: 1 | AA89: 208 | AB89: 208.1 | AC89: 228.1 | AD89: 220.1 | AF89: 21 | AH89: N
A90: 89 | B90: Jameis Winston | C90: TAM | D90: QB | E90: 24 | F90: 11 | G90: 9 | H90: 244 | I90: 378 | J90: 2992 | K90: 19 | L90: 14 | M90: 49 | N90: 281 | O90: 5.73 | P90: 1 | Q90: 0 | R90: 0 | S90: 0 | T90: 0 | U90: 0 | V90: 7 | W90: 3 | X90: 1 | Y90: 0 | Z90: 0 | AA90: 196 | AB90: 195.8 | AC90: 218.8 | AD90: 209.8 | AF90: 22 | AH90: N
A91: 90 | B91: Carson Wentz | C91: PHI | D91: QB | E91: 26 | F91: 11 | G91: 11 | H91: 279 | I91: 401 | J91: 3074 | K91: 21 | L91: 7 | M91: 34 | N91: 93 | O91: 2.74 | P91: 0 | Q91: 1 | R91: 1 | S91: 4 | T91: 4 | U91: 0 | V91: 9 | W91: 6 | X91: 0 | Y91: 0 | Z91: 1 | AA91: 193 | AB91: 193.7 | AC91: 209.7 | AD91: 200.2 | AF91: 23 | AH91: N
... A538: 537 | B538: Tim White | C538: BAL | D538: WR | E538: 24 | F538: 3 | G538: 0 | H538: 0 | I538: 0 | J538: 0 | K538: 0 | L538: 0 | M538: 0 | N538: 0 | O538: 0 | P538: 0 | Q538: 1 | R538: 1 | S538: 14 | T538: 14 | U538: 0 | V538: 1 | W538: 0 | X538: 0 | Y538: 0 | Z538: 0 | AA538: 1 | AB538: 2.4 | AC538: 2.4 | AD538: 1.9 | AF538: 192 | AH538: N
A539: 538 | B539: Saeed Blacknall | C539: OAK | E539: 22 | F539: 1 | G539: 0 | H539: 0 | I539: 0 | J539: 0 | K539: 0 | L539: 0 | M539: 0 | N539: 0 | O539: 0 | P539: 0 | Q539: 0 | R539: 0 | S539: 0 | T539: 0 | U539: 0 | V539: 0 | W539: 0 | X539: 0 | Y539: 0 | Z539: 0 | AF539: 210 | AH539: N
A540: 539 | B540: Daniel Brown | C540: CHI | E540: 26 | F540: 14 | G540: 0 | H540: 0 | I540: 0 | J540: 0 | K540: 0 | L540: 0 | M540: 0 | N540: 0 | O540: 0 | P540: 0 | Q540: 0 | R540: 0 | S540: 0 | T540: 0 | U540: 0 | V540: 0 | W540: 0 | X540: 0 | Y540: 0 | Z540: 0 | AF540: 119 | AH540: N
A541: 540 | B541: Deante Burton | C541: 2TM | E541: 24 | F541: 3 | G541: 0 | H541: 0 | I541: 0 | J541: 0 | K541: 0 | L541: 0 | M541: 0 | N541: 0 | O541: 0 | P541: 0 | Q541: 0 | R541: 0 | S541: 0 | T541: 0 | U541: 0 | V541: 0 | W541: 0 | X541: 0 | Y541: 0 | Z541: 0 | AF541: 211 | AH541: N
A542: 541 | B542: Jehu Chesson | C542: WAS | D542: WR | E542: 25 | F542: 12 | G542: 0 | H542: 0 | I542: 0 | J542: 0 | K542: 0 | L542: 0 | M542: 1 | N542: -4 | O542: -4 | P542: 0 | Q542: 2 | R542: 1 | S542: 7 | T542: 7 | U542: 0 | V542: 0 | W542: 0 | X542: 0 | Y542: 0 | Z542: 0 | AB542: 1.3 | AC542: 1.3 | AD542: 0.8 | AF542: 205 | AH542: N
A543: 542 | B543: Lavon Coleman | C543: GNB | E543: 24 | F543: 1 | G543: 0 | H543: 0 | I543: 0 | J543: 0 | K543: 0 | L543: 0 | M543: 0 | N543: 0 | O543: 0 | P543: 0 | Q543: 0 | R543: 0 | S543: 0 | T543: 0 | U543: 0 | V543: 0 | W543: 0 | X543: 0 | Y543: 0 | Z543: 0 | AF543: 162 | AH543: N
A544: 543 | B544: Stacy Coley | C544: 2TM | E544: 24 | F544: 3 | G544: 0 | H544: 0 | I544: 0 | J544: 0 | K544: 0 | L544: 0 | M544: 0 | N544: 0 | O544: 0 | P544: 0 | Q544: 1 | R544: 0 | S544: 0 | T544: 0 | U544: 0 | V544: 1 | W544: 0 | X544: 0 | Y544: 0 | Z544: 0 | AF544: 212 | AH544: N
A545: 544 | B545: Pharoh Cooper | C545: 2TM | E545: 23 | F545: 7 | G545: 0 | H545: 0 | I545: 0 | J545: 0 | K545: 0 | L545: 0 | M545: 0 | N545: 0 | O545: 0 | P545: 0 | Q545: 1 | R545: 0 | S545: 0 | T545: 0 | U545: 0 | V545: 1 | W545: 0 | X545: 0 | Y545: 0 | Z545: 0 | AF545: 213 | AH545: N
...

Sheet 2019 Stats
A1: Rk | B1: Player | C1: Tm | D1: FantPos | E1: Age | F1: Games G | G1: Games GS | H1: Passing Cmp | I1: Passing Att | J1: Passing Yds | K1: Passing TD | L1: Passing Int | M1: Rushing Att | N1: Rushing Yds | O1: Rushing Y/A | P1: Rushing TD | Q1: Receiving Tgt | R1: Receiving Rec | S1: Receiving Yds | T1: Receiving Y/R | U1: Receiving TD | V1: Fumbles Fmb | W1: Fumbles FL | X1: Scoring TD | Y1: Scoring 2PM | Z1: Scoring 2PP | AA1: Fantasy FantPt | AB1: Fantasy PPR | AC1: Fantasy DKPt | AD1: Fantasy FDPt | AE1: Fantasy VBD | AF1: Fantasy PosRank | AG1: Fantasy OvRank | AH1: Custom
A2: 1 | B2: Christian McCaffrey | C2: CAR | D2: RB | E2: 23 | F2: 16 | G2: 16 | H2: 0 | I2: 2 | J2: 0 | K2: 0 | L2: 0 | M2: 287 | N2: 1387 | O2: 4.83 | P2: 15 | Q2: 142 | R2: 116 | S2: 1005 | T2: 8.66 | U2: 4 | V2: 1 | W2: 0 | X2: 19 | Y2: 1 | Z2: 0 | AA2: 355 | AB2: 471.2 | AC2: 477.2 | AD2: 413.2 | AE2: 215 | AF2: 1 | AG2: 1 | AH2: N
A3: 2 | B3: Lamar Jackson | C3: BAL | D3: QB | E3: 22 | F3: 15 | G3: 15 | H3: 265 | I3: 401 | J3: 3127 | K3: 36 | L3: 6 | M3: 176 | N3: 1206 | O3: 6.85 | P3: 7 | Q3: 0 | R3: 0 | S3: 0 | T3: 0 | U3: 0 | V3: 9 | W3: 2 | X3: 7 | Y3: 0 | Z3: 0 | AA3: 416 | AB3: 415.7 | AC3: 429.7 | AD3: 421.7 | AE3: 152 | AF3: 1 | AG3: 2 | AH3: N
A4: 3 | B4: Derrick Henry | C4: TEN | D4: RB | E4: 25 | F4: 15 | G4: 15 | H4: 0 | I4: 0 | J4: 0 | K4: 0 | L4: 0 | M4: 303 | N4: 1540 | O4: 5.08 | P4: 16 | Q4: 24 | R4: 18 | S4: 206 | T4: 11.44 | U4: 2 | V4: 5 | W4: 3 | X4: 18 | Y4: 0 | Z4: 0 | AA4: 277 | AB4: 294.6 | AC4: 303.6 | AD4: 285.6 | AE4: 136 | AF4: 2 | AG4: 3 | AH4: N
A5: 4 | B5: Aaron Jones | C5: GNB | D5: RB | E5: 25 | F5: 16 | G5: 16 | H5: 0 | I5: 0 | J5: 0 | K5: 0 | L5: 0 | M5: 236 | N5: 1084 | O5: 4.59 | P5: 16 | Q5: 68 | R5: 49 | S5: 474 | T5: 9.67 | U5: 3 | V5: 3 | W5: 2 | X5: 19 | Y5: 0 | Z5: 0 | AA5: 266 | AB5: 314.8 | AC5: 322.8 | AD5: 290.3 | AE5: 125 | AF5: 3 | AG5: 4 | AH5: N
A6: 5 | B6: Ezekiel Elliott | C6: DAL | D6: RB | E6: 24 | F6: 16 | G6: 16 | H6: 0 | I6: 0 | J6: 0 | K6: 0 | L6: 0 | M6: 301 | N6: 1357 | O6: 4.51 | P6: 12 | Q6: 71 | R6: 54 | S6: 420 | T6: 7.78 | U6: 2 | V6: 3 | W6: 2 | X6: 14 | Y6: 0 | Z6: 0 | AA6: 258 | AB6: 311.7 | AC6: 319.7 | AD6: 284.7 | AE6: 117 | AF6: 4 | AG6: 5 | AH6: N
A7: 6 | B7: Dalvin Cook | C7: MIN | D7: RB | E7: 24 | F7: 14 | G7: 14 | H7: 0 | I7: 0 | J7: 0 | K7: 0 | L7: 0 | M7: 250 | N7: 1135 | O7: 4.54 | P7: 13 | Q7: 63 | R7: 53 | S7: 519 | T7: 9.79 | U7: 0 | V7: 4 | W7: 2 | X7: 13 | Y7: 0 | Z7: 0 | AA7: 239 | AB7: 292.4 | AC7: 300.4 | AD7: 265.9 | AE7: 99 | AF7: 5 | AG7: 6 | AH7: N
A8: 7 | B8: Michael Thomas | C8: NOR | D8: WR | E8: 26 | F8: 16 | G8: 15 | H8: 0 | I8: 0 | J8: 0 | K8: 0 | L8: 0 | M8: 1 | N8: -9 | O8: -9 | P8: 0 | Q8: 185 | R8: 149 | S8: 1725 | T8: 11.58 | U8: 9 | V8: 1 | W8: 0 | X8: 9 | Y8: 0 | Z8: 0 | AA8: 226 | AB8: 374.6 | AC8: 377.6 | AD8: 300.1 | AE8: 97 | AF8: 1 | AG8: 7 | AH8: N
A9: 8 | B9: Travis Kelce | C9: KAN | D9: TE | E9: 30 | F9: 16 | G9: 16 | H9: 0 | I9: 0 | J9: 0 | K9: 0 | L9: 0 | M9: 1 | N9: 4 | O9: 4 | P9: 1 | Q9: 136 | R9: 97 | S9: 1229 | T9: 12.67 | U9: 5 | V9: 1 | W9: 1 | X9: 6 | Y9: 0 | Z9: 0 | AA9: 157 | AB9: 254.3 | AC9: 258.3 | AD9: 205.8 | AE9: 80 | AF9: 1 | AG9: 8 | AH9: N
A10: 9 | B10: Nick Chubb | C10: CLE | D10: RB | E10: 24 | F10: 16 | G10: 16 | H10: 0 | I10: 0 | J10: 0 | K10: 0 | L10: 0 | M10: 298 | N10: 1494 | O10: 5.01 | P10: 8 | Q10: 49 | R10: 36 | S10: 278 | T10: 7.72 | U10: 0 | V10: 3 | W10: 3 | X10: 8 | Y10: 0 | Z10: 0 | AA10: 219 | AB10: 255.2 | AC10: 264.2 | AD10: 237.2 | AE10: 79 | AF10: 6 | AG10: 9 | AH10: N
A11: 10 | B11: Austin Ekeler | C11: LAC | D11: RB | E11: 24 | F11: 16 | G11: 8 | H11: 0 | I11: 0 | J11: 0 | K11: 0 | L11: 0 | M11: 132 | N11: 557 | O11: 4.22 | P11: 3 | Q11: 108 | R11: 92 | S11: 993 | T11: 10.79 | U11: 8 | V11: 3 | W11: 2 | X11: 11 | Y11: 0 | Z11: 0 | AA11: 217 | AB11: 309 | AC11: 317 | AD11: 263 | AE11: 76 | AF11: 7 | AG11: 10 | AH11: N
A12: 11 | B12: Mark Ingram | C12: BAL | D12: RB | E12: 30 | F12: 15 | G12: 15 | H12: 0 | I12: 0 | J12: 0 | K12: 0 | L12: 0 | M12: 202 | N12: 1018 | O12: 5.04 | P12: 10 | Q12: 29 | R12: 26 | S12: 247 | T12: 9.5 | U12: 5 | V12: 2 | W12: 2 | X12: 15 | Y12: 2 | Z12: 0 | AA12: 217 | AB12: 242.5 | AC12: 250.5 | AD12: 229.5 | AE12: 76 | AF12: 8 | AG12: 11 | AH12: N
A13: 12 | B13: Dak Prescott | C13: DAL | D13: QB | E13: 26 | F13: 16 | G13: 16 | H13: 388 | I13: 596 | J13: 4902 | K13: 30 | L13: 11 | M13: 52 | N13: 277 | O13: 5.33 | P13: 3 | Q13: 0 | R13: 0 | S13: 0 | T13: 0 | U13: 0 | V13: 6 | W13: 2 | X13: 3 | Y13: 0 | Z13: 1 | AA13: 338 | AB13: 337.8 | AC13: 356.8 | AD13: 348.8 | AE13: 74 | AF13: 2 | AG13: 12 | AH13: N
... A75: 74 | B75: Davante Adams | C75: GNB | D75: WR | E75: 27 | F75: 12 | G75: 12 | H75: 0 | I75: 0 | J75: 0 | K75: 0 | L75: 0 | M75: 0 | N75: 0 | O75: 0 | P75: 0 | Q75: 127 | R75: 83 | S75: 997 | T75: 12.01 | U75: 5 | V75: 2 | W75: 1 | X75: 5 | Y75: 1 | Z75: 0 | AA75: 130 | AB75: 212.7 | AC75: 216.7 | AD75: 171.2 | AE75: 1 | AF75: 29 | AG75: 74 | AH75: N
A76: 75 | B76: Sony Michel | C76: NWE | D76: RB | E76: 24 | F76: 16 | G76: 14 | H76: 0 | I76: 0 | J76: 0 | K76: 0 | L76: 0 | M76: 247 | N76: 912 | O76: 3.69 | P76: 7 | Q76: 20 | R76: 12 | S76: 94 | T76: 7.83 | U76: 0 | V76: 2 | W76: 1 | X76: 7 | Y76: 0 | Z76: 0 | AA76: 141 | AB76: 152.6 | AC76: 156.6 | AD76: 146.6 | AF76: 24 | AG76: 75 | AH76: N
A77: 76 | B77: Tom Brady | C77: NWE | D77: QB | E77: 42 | F77: 16 | G77: 16 | H77: 373 | I77: 613 | J77: 4057 | K77: 24 | L77: 8 | M77: 26 | N77: 34 | O77: 1.31 | P77: 3 | Q77: 0 | R77: 0 | S77: 0 | T77: 0 | U77: 0 | V77: 4 | W77: 1 | X77: 3 | Y77: 0 | Z77: 1 | AA77: 264 | AB77: 263.7 | AC77: 275.7 | AD77: 271.7 | AF77: 12 | AG77: 76 | AH77: N
A78: 77 | B78: Jason Witten | C78: DAL | D78: TE | E78: 37 | F78: 16 | G78: 16 | H78: 0 | I78: 0 | J78: 0 | K78: 0 | L78: 0 | M78: 0 | N78: 0 | O78: 0 | P78: 0 | Q78: 83 | R78: 63 | S78: 529 | T78: 8.4 | U78: 4 | V78: 1 | W78: 1 | X78: 4 | Y78: 1 | Z78: 0 | AA78: 77 | AB78: 139.9 | AC78: 143.9 | AD78: 108.4 | AF78: 12 | AG78: 77 | AH78: N
A79: 78 | B79: Michael Burton | C79: WAS | E79: 27 | F79: 10 | G79: 2 | H79: 0 | I79: 0 | J79: 0 | K79: 0 | L79: 0 | M79: 0 | N79: 0 | O79: 0 | P79: 0 | Q79: 1 | R79: 0 | S79: 0 | T79: 0 | U79: 0 | V79: 0 | W79: 0 | X79: 0 | Y79: 0 | Z79: 0 | AF79: 1 | AG79: 78 | AH79: N
A80: 79 | B80: Jared Goff | C80: LAR | D80: QB | E80: 25 | F80: 16 | G80: 16 | H80: 394 | I80: 626 | J80: 4638 | K80: 22 | L80: 16 | M80: 33 | N80: 40 | O80: 1.21 | P80: 2 | Q80: 0 | R80: 0 | S80: 0 | T80: 0 | U80: 0 | V80: 10 | W80: 5 | X80: 2 | Y80: 0 | Z80: 0 | AA80: 248 | AB80: 247.5 | AC80: 271.5 | AD80: 263.5 | AF80: 13 | AH80: N
A81: 80 | B81: Jimmy Garoppolo | C81: SFO | D81: QB | E81: 28 | F81: 16 | G81: 16 | H81: 329 | I81: 476 | J81: 3978 | K81: 27 | L81: 13 | M81: 46 | N81: 62 | O81: 1.35 | P81: 1 | Q81: 0 | R81: 0 | S81: 0 | T81: 0 | U81: 0 | V81: 10 | W81: 5 | X81: 1 | Y81: 0 | Z81: 2 | AA81: 247 | AB81: 247.3 | AC81: 268.3 | AD81: 260.3 | AF81: 14 | AH81: N
A82: 81 | B82: Derek Carr | C82: OAK | D82: QB | E82: 28 | F82: 16 | G82: 16 | H82: 361 | I82: 513 | J82: 4054 | K82: 21 | L82: 8 | M82: 27 | N82: 82 | O82: 3.04 | P82: 2 | Q82: 0 | R82: 0 | S82: 0 | T82: 0 | U82: 0 | V82: 7 | W82: 3 | X82: 2 | Y82: 0 | Z82: 0 | AA82: 244 | AB82: 244.4 | AC82: 258.4 | AD82: 252.4 | AF82: 16 | AH82: N
A83: 82 | B83: Kirk Cousins | C83: MIN | D83: QB | E83: 31 | F83: 15 | G83: 15 | H83: 307 | I83: 444 | J83: 3603 | K83: 26 | L83: 6 | M83: 31 | N83: 63 | O83: 2.03 | P83: 1 | Q83: 1 | R83: 0 | S83: 0 | T83: 0 | U83: 0 | V83: 10 | W83: 3 | X83: 1 | Y83: 0 | Z83: 1 | AA83: 244 | AB83: 244.4 | AC83: 256.4 | AD83: 250.4 | AF83: 15 | AH83: N
A84: 83 | B84: Ryan Fitzpatrick | C84: MIA | D84: QB | E84: 37 | F84: 15 | G84: 13 | H84: 311 | I84: 502 | J84: 3529 | K84: 20 | L84: 13 | M84: 54 | N84: 243 | O84: 4.5 | P84: 4 | Q84: 0 | R84: 0 | S84: 0 | T84: 0 | U84: 0 | V84: 9 | W84: 2 | X84: 4 | Y84: 0 | Z84: 1 | AA84: 241 | AB84: 241.5 | AC84: 262.5 | AD84: 254.5 | AF84: 17 | AH84: N
A85: 84 | B85: Philip Rivers | C85: LAC | D85: QB | E85: 38 | F85: 16 | G85: 16 | H85: 390 | I85: 591 | J85: 4615 | K85: 23 | L85: 20 | M85: 12 | N85: 29 | O85: 2.42 | P85: 0 | Q85: 0 | R85: 0 | S85: 0 | T85: 0 | U85: 0 | V85: 8 | W85: 3 | X85: 0 | Y85: 0 | Z85: 1 | AA85: 236 | AB85: 235.5 | AC85: 261.5 | AD85: 255.5 | AF85: 18 | AH85: N
A86: 85 | B86: Baker Mayfield | C86: CLE | D86: QB | E86: 24 | F86: 16 | G86: 16 | H86: 317 | I86: 534 | J86: 3827 | K86: 22 | L86: 21 | M86: 28 | N86: 141 | O86: 5.04 | P86: 3 | Q86: 0 | R86: 0 | S86: 0 | T86: 0 | U86: 0 | V86: 6 | W86: 2 | X86: 3 | Y86: 0 | Z86: 1 | AA86: 229 | AB86: 229.2 | AC86: 258.2 | AD86: 250.2 | AF86: 20 | AH86: N
A87: 86 | B87: Gardner Minshew II | C87: JAX | D87: QB | E87: 23 | F87: 14 | G87: 12 | H87: 285 | I87: 470 | J87: 3271 | K87: 21 | L87: 6 | M87: 67 | N87: 344 | O87: 5.13 | P87: 0 | Q87: 0 | R87: 0 | S87: 0 | T87: 0 | U87: 0 | V87: 13 | W87: 7 | X87: 0 | Y87: 0 | Z87: 3 | AA87: 229 | AB87: 229.2 | AC87: 248.2 | AD87: 235.2 | AF87: 19 | AH87: N
A88: 87 | B88: Drew Brees | C88: NOR | D88: QB | E88: 40 | F88: 11 | G88: 11 | H88: 281 | I88: 378 | J88: 2979 | K88: 27 | L88: 4 | M88: 9 | N88: -4 | O88: -0.44 | P88: 1 | Q88: 0 | R88: 0 | S88: 0 | T88: 0 | U88: 0 | V88: 0 | W88: 0 | X88: 1 | Y88: 0 | Z88: 0 | AA88: 225 | AB88: 224.8 | AC88: 231.8 | AD88: 228.8 | AF88: 21 | AH88: N
A89: 88 | B89: Ryan Tannehill | C89: TEN | D89: QB | E89: 31 | F89: 12 | G89: 10 | H89: 201 | I89: 286 | J89: 2742 | K89: 22 | L89: 6 | M89: 43 | N89: 185 | O89: 4.3 | P89: 4 | Q89: 0 | R89: 0 | S89: 0 | T89: 0 | U89: 0 | V89: 6 | W89: 3 | X89: 4 | Y89: 1 | Z89: 0 | AA89: 224 | AB89: 224.2 | AC89: 239.2 | AD89: 230.2 | AF89: 22 | AH89: N
A90: 89 | B90: Jacoby Brissett | C90: IND | D90: QB | E90: 27 | F90: 15 | G90: 15 | H90: 272 | I90: 447 | J90: 2942 | K90: 18 | L90: 6 | M90: 56 | N90: 228 | O90: 4.07 | P90: 4 | Q90: 1 | R90: 1 | S90: 2 | T90: 2 | U90: 0 | V90: 7 | W90: 5 | X90: 4 | Y90: 0 | Z90: 1 | AA90: 217 | AB90: 217.7 | AC90: 234.7 | AD90: 223.2 | AF90: 23 | AH90: N
A91: 90 | B91: Daniel Jones | C91: NYG | D91: QB | E91: 22 | F91: 13 | G91: 12 | H91: 284 | I91: 459 | J91: 3027 | K91: 24 | L91: 12 | M91: 45 | N91: 279 | O91: 6.2 | P91: 2 | Q91: 0 | R91: 0 | S91: 0 | T91: 0 | U91: 0 | V91: 18 | W91: 11 | X91: 2 | Y91: 0 | Z91: 2 | AA91: 215 | AB91: 215 | AC91: 244 | AD91: 227 | AF91: 24 | AH91: N
... A537: 536 | B537: Dexter Williams | C537: GNB | D537: RB | E537: 22 | F537: 4 | G537: 0 | H537: 0 | I537: 0 | J537: 0 | K537: 0 | L537: 0 | M537: 5 | N537: 11 | O537: 2.2 | P537: 0 | Q537: 0 | R537: 0 | S537: 0 | T537: 0 | U537: 0 | V537: 0 | W537: 0 | X537: 0 | Y537: 0 | Z537: 0 | AA537: 1 | AB537: 1.1 | AC537: 1.1 | AD537: 1.1 | AF537: 140 | AH537: N
A538: 537 | B538: Jerell Adams | C538: HOU | E538: 27 | F538: 1 | G538: 0 | H538: 0 | I538: 0 | J538: 0 | K538: 0 | L538: 0 | M538: 0 | N538: 0 | O538: 0 | P538: 0 | Q538: 0 | R538: 0 | S538: 0 | T538: 0 | U538: 0 | V538: 0 | W538: 0 | X538: 0 | Y538: 0 | Z538: 0 | AF538: 125 | AH538: N
A539: 538 | B539: Stephen Anderson | C539: LAC | E539: 26 | F539: 1 | G539: 0 | H539: 0 | I539: 0 | J539: 0 | K539: 0 | L539: 0 | M539: 0 | N539: 0 | O539: 0 | P539: 0 | Q539: 0 | R539: 0 | S539: 0 | T539: 0 | U539: 0 | V539: 0 | W539: 0 | X539: 0 | Y539: 0 | Z539: 0 | AF539: 120 | AH539: N
A540: 539 | B540: Evan Baylis | C540: GNB | E540: 26 | F540: 3 | G540: 0 | H540: 0 | I540: 0 | J540: 0 | K540: 0 | L540: 0 | M540: 0 | N540: 0 | O540: 0 | P540: 0 | Q540: 0 | R540: 0 | S540: 0 | T540: 0 | U540: 0 | V540: 0 | W540: 0 | X540: 0 | Y540: 0 | Z540: 0 | AF540: 130 | AH540: N
A541: 540 | B541: Kendall Blanton | C541: LAR | E541: 24 | F541: 1 | G541: 0 | H541: 0 | I541: 0 | J541: 0 | K541: 0 | L541: 0 | M541: 0 | N541: 0 | O541: 0 | P541: 0 | Q541: 0 | R541: 0 | S541: 0 | T541: 0 | U541: 0 | V541: 0 | W541: 0 | X541: 0 | Y541: 0 | Z541: 0 | AF541: 117 | AH541: N
A542: 541 | B542: Tim Boyle | C542: GNB | D542: QB | E542: 25 | F542: 3 | G542: 0 | H542: 3 | I542: 4 | J542: 15 | K542: 0 | L542: 0 | M542: 5 | N542: -7 | O542: -1.4 | P542: 0 | Q542: 0 | R542: 0 | S542: 0 | T542: 0 | U542: 0 | V542: 0 | W542: 0 | X542: 0 | Y542: 0 | Z542: 0 | AB542: -0.1 | AC542: -0.1 | AD542: -0.1 | AF542: 68 | AH542: N
A543: 542 | B543: Deante Burton | C543: DAL | E543: 25 | F543: 3 | G543: 0 | H543: 0 | I543: 0 | J543: 0 | K543: 0 | L543: 0 | M543: 0 | N543: 0 | O543: 0 | P543: 0 | Q543: 0 | R543: 0 | S543: 0 | T543: 0 | U543: 0 | V543: 0 | W543: 0 | X543: 0 | Y543: 0 | Z543: 0 | AF543: 224 | AH543: N
A544: 543 | B544: Trenton Cannon | C544: NYJ | E544: 25 | F544: 4 | G544: 0 | H544: 0 | I544: 0 | J544: 0 | K544: 0 | L544: 0 | M544: 0 | N544: 0 | O544: 0 | P544: 0 | Q544: 0 | R544: 0 | S544: 0 | T544: 0 | U544: 0 | V544: 0 | W544: 0 | X544: 0 | Y544: 0 | Z544: 0 | AF544: 156 | AH544: N
A545: 544 | B545: Garrett Celek | C545: SFO | E545: 31 | F545: 5 | G545: 1 | H545: 0 | I545: 0 | J545: 0 | K545: 0 | L545: 0 | M545: 0 | N545: 0 | O545: 0 | P545: 0 | Q545: 0 | R545: 0 | S545: 0 | T545: 0 | U545: 0 | V545: 0 | W545: 0 | X545: 0 | Y545: 0 | Z545: 0 | AF545: 121 | AH545: N
A546: 545 | B546: Jordan Chunn | C546: DAL | E546: 24 | F546: 1 | G546: 0 | H546: 0 | I546: 0 | J546: 0 | K546: 0 | L546: 0 | M546: 0 | N546: 0 | O546: 0 | P546: 0 | Q546: 0 | R546: 0 | S546: 0 | T546: 0 | U546: 0 | V546: 0 | W546: 0 | X546: 0 | Y546: 0 | Z546: 0 | AF546: 163 | AH546: N
...

Sheet Fanduel Export
AJ1: 1 = playing, 0 = not playing | AK1: Attempts * playing | AL1: Make Sure Backup QB's are excluded | AN1: 1 pt/ 25 yds | AQ1: pro rata off of # of passes | AR1: .5 pt/reception | AU1: 1 pt/10 yrds | AZ1: 1 pt/10 yrds
A2: Week 1 pulled 8-10 | O2: Trimmed Full name | T2: 2020 Passing | Y2: 2020 Receiving | AD2: 2020 Rushing | AO2: Algorithm Columns
A3: ID | B3: Position | C3: First Name | D3: Nickname | E3: Last Name | F3: FPPG | G3: Played | H3: Salary | I3: Game | J3: Team | K3: Opponent | L3: Injury Indicator | M3: Injury Detail | N3: Tier | O3: Full Name | P3: Lookup Name | Q3: Def Passing Yds/att | R3: Def Rushing yds/att | S3: Def Passing Yds/Reception | T3: Attempts/gm | U3: Yards/gm | V3: Yards/Attempt | W3: Passing TD | X3: Targets Per Game | Y3: Receptions per game | Z3: Yards per game | AA3: Yards/reception | AB3: Long | AC3: Receiving TDs | AD3: Rushes | AE3: Rushing Yards | AF3: Yards/Att | AG3: Rushing TDs | AH3: # of Passes | AI3: # of Runs | AJ3: Playing? | AK3: # of Attempts | AL3: Adjusted Projected Attempts | AM3: Pass Yards per completion | AN3: Passing yards | AO3: Targets per game | AP3: Projected Team Targets | AQ3: Adjusted Projected Targets | AR3: Receptions | AS3: Adjusted Projected Receptions | AT3: Yards per Reception | AU3: Receiving yards | AV3: Rushes | AW3: Team Rushes | AX3: Adjusted Projected Rushes | AY3: Yards per Attempt | AZ3: Rushing yards | BA3: Fanduel Pts | BB3: Value per $1k | BC3: Targets per $1K | BD3: Name | BE3: Salary | BF3: Position
A4: 47691-55050 | B4: RB | C4: Christian | D4: Christian McCaffrey | E4: McCaffrey | F4: 25.825001 | G4: 16 | H4: 10000 | I4: LV@CAR | J4: CAR | K4: LV | O4: =D4 -> Christian McCaffrey | P4: =IFERROR(VLOOKUP(O:O,'Name Bridge'!A:B,2,FALSE),O:O) -> Christian McCaffrey | Q4: =VLOOKUP($K4,'Defensive Stats'!$AC:$AH,2,FALSE) -> 7.8079848 | R4: =VLOOKUP($K4,'Defensive Stats'!$AC:$AH,4,FALSE) -> 3.8765432 | S4: =VLOOKUP($K4,'Defensive Stats'!$AC:$AH,6,FALSE) -> 12.186944 | T4: =IFERROR(VLOOKUP($P4,Passing!$C:$AF,9,FALSE)/VLOOKUP($P4,Passing!$C:$AF,5,FALSE),0) -> 0.125 | U4: =IFERROR(VLOOKUP($P4,Passing!$C:$AF,11,FALSE)/VLOOKUP($P4,Passing!$C:$AF,5,FALSE),0) -> 0 | V4: =IFERROR(VLOOKUP($P4,Passing!$C:$AF,18,FALSE),0) -> 0.0 | W4: =IFERROR(VLOOKUP($P4,Passing!$C:$AF,12,FALSE)/VLOOKUP($P4,Passing!$C:$AF,5,FALSE),0) -> 0 | X4: =IFERROR(IF(OR($B4="D",$B4="K"),0,VLOOKUP($P4,Receiving!$C:$T,7,FALSE)/VLOOKUP($P4,Receiving!$C:$T,5,FALSE)),0)*$AJ4 -> 8.875 | Y4: =IFERROR(VLOOKUP($P4,Receiving!$C:$T,8,FALSE)/VLOOKUP($P4,Receiving!$C:$T,5,FALSE),0) -> 7.25 | Z4: =IFERROR(VLOOKUP($P4,Receiving!$C:$T,10,FALSE)/VLOOKUP($P4,Receiving!$C:$T,5,FALSE),0) -> 62.8125 | AA4: =IFERROR(VLOOKUP($P4,Receiving!$C:$T,11,FALSE),0) -> 8.7 | AB4: =IFERROR(VLOOKUP($P4,Receiving!$C:$T,14,FALSE),0) -> 28 | AC4: =IFERROR(VLOOKUP($P4,Receiving!$C:$T,11,FALSE)/VLOOKUP($P4,Receiving!$C:$T,5,FALSE),0) -> 0.54375 | AD4: =IFERROR(VLOOKUP($P4,Rushing!$C:$P,7,FALSE)/VLOOKUP($P4,Rushing!$C:$P,5,FALSE),0) -> 17.9375 | AE4: =IFERROR(VLOOKUP($P4,Rushing!$C:$P,8,FALSE)/VLOOKUP($P4,Rushing!$C:$P,5,FALSE),0) -> 86.6875 | AF4: =IFERROR(VLOOKUP($P4,Rushing!$C:$P,12,FALSE),0) -> 4.8 | AG4: =IFERROR(VLOOKUP($P4,Rushing!$C:$P,9,FALSE)/VLOOKUP($P4,Rushing!$C:$P,5,FALSE),0) -> 0.9375 | AH4: =VLOOKUP($J4,'Vegas Odds'!$B:$S,18,FALSE) -> 42.975625 | AI4: =VLOOKUP($J4,'Vegas Odds'!$B:$S,17,FALSE) -> 20.224375 | AJ4: 1 | AK4: =T4*AJ4 -> 0.125 | AL4: =IF(AND(AJ4=1,B4="QB"),AH4,0) -> 0 | AM4: =V4/Team_Defense_Table[[#Totals],[Passing yds/att]]*'Fanduel Export'!Q4 -> 0 | AN4: =AM4*AK4 -> 0 | AO4: =IFERROR(IF(OR($B4="D",$B4="K"),0,VLOOKUP($P4,Receiving!$C:$T,7,FALSE)/VLOOKUP($P4,Receiving!$C:$T,5,FALSE)),0)*$AJ4 -> 8.875 | AP4: =SUMIF($J:$J,$J4,AO:AO) -> 35.359295 | AQ4: =AO4/AP4*AH4 -> 10.786659 | AR4: =Y4*AJ4 -> 7.25 | AS4: =IFERROR(AR4/AO4*AQ4,0) -> 8.8116372 | AT4: =AA4/Team_Defense_Table[[#Totals],[Yards per completion]]*'Fanduel Export'!S4 -> 9.9850473 | AU4: =AR4*AT4 -> 72.391593 | AV4: =AD4*AJ4 -> 17.9375 | AW4: =SUMIF($J:$J,$J4,AV:AV) -> 28.778312 | AX4: =IFERROR(AV4/AW4*AI4,0) -> 12.605838 | AY4: =AF4/Team_Defense_Table[[#Totals],[Rushing Y/A]]*R4 -> 4.3147611 | AZ4: =AY4*AV4 -> 77.396028 | BA4: =AN4/25+AU4/10+AZ4/10+AR4*0.5 -> 18.603762 | BB4: =BA4/(H4/1000) -> 1.8603762 | BC4: =AO4/(H4/1000) -> 0.8875 | BE4: =H4 -> 10000 | BF4: =B4 -> RB
A5: 47691-63115 | B5: QB | C5: Lamar | D5: Lamar Jackson | E5: Jackson | F5: 28.112 | G5: 15 | H5: 9400 | I5: CLE@BAL | J5: BAL | K5: CLE | O5: =D5 -> Lamar Jackson | P5: =IFERROR(VLOOKUP(O:O,'Name Bridge'!A:B,2,FALSE),O:O) -> Lamar Jackson | Q5: =VLOOKUP($K5,'Defensive Stats'!$AC:$AH,2,FALSE) -> 6.7641326 | R5: =VLOOKUP($K5,'Defensive Stats'!$AC:$AH,4,FALSE) -> 5 | S5: =VLOOKUP($K5,'Defensive Stats'!$AC:$AH,6,FALSE) -> 10.91195 | T5: =IFERROR(VLOOKUP($P5,Passing!$C:$AF,9,FALSE)/VLOOKUP($P5,Passing!$C:$AF,5,FALSE),0) -> 26.733333 | U5: =IFERROR(VLOOKUP($P5,Passing!$C:$AF,11,FALSE)/VLOOKUP($P5,Passing!$C:$AF,5,FALSE),0) -> 208.46667 | V5: =IFERROR(VLOOKUP($P5,Passing!$C:$AF,18,FALSE),0) -> 7.8 | W5: =IFERROR(VLOOKUP($P5,Passing!$C:$AF,12,FALSE)/VLOOKUP($P5,Passing!$C:$AF,5,FALSE),0) -> 2.4 | X5: =IFERROR(IF(OR($B5="D",$B5="K"),0,VLOOKUP($P5,Receiving!$C:$T,7,FALSE)/VLOOKUP($P5,Receiving!$C:$T,5,FALSE)),0)*$AJ5 -> 0 | Y5: =IFERROR(VLOOKUP($P5,Receiving!$C:$T,8,FALSE)/VLOOKUP($P5,Receiving!$C:$T,5,FALSE),0) -> 0 | Z5: =IFERROR(VLOOKUP($P5,Receiving!$C:$T,10,FALSE)/VLOOKUP($P5,Receiving!$C:$T,5,FALSE),0) -> 0 | AA5: =IFERROR(VLOOKUP($P5,Receiving!$C:$T,11,FALSE),0) -> 0 | AB5: =IFERROR(VLOOKUP($P5,Receiving!$C:$T,14,FALSE),0) -> 0 | AC5: =IFERROR(VLOOKUP($P5,Receiving!$C:$T,11,FALSE)/VLOOKUP($P5,Receiving!$C:$T,5,FALSE),0) -> 0 | AD5: =IFERROR(VLOOKUP($P5,Rushing!$C:$P,7,FALSE)/VLOOKUP($P5,Rushing!$C:$P,5,FALSE),0) -> 11.733333 | AE5: =IFERROR(VLOOKUP($P5,Rushing!$C:$P,8,FALSE)/VLOOKUP($P5,Rushing!$C:$P,5,FALSE),0) -> 80.4 | AF5: =IFERROR(VLOOKUP($P5,Rushing!$C:$P,12,FALSE),0) -> 6.9 | AG5: =IFERROR(VLOOKUP($P5,Rushing!$C:$P,9,FALSE)/VLOOKUP($P5,Rushing!$C:$P,5,FALSE),0) -> 0.46666667 | AH5: =VLOOKUP($J5,'Vegas Odds'!$B:$S,18,FALSE) -> 12.779864 | AI5: =VLOOKUP($J5,'Vegas Odds'!$B:$S,17,FALSE) -> 50.520136 | AJ5: 1 | AK5: =T5*AJ5 -> 26.733333 | AL5: =IF(AND(AJ5=1,B5="QB"),AH5,0) -> 12.779864 | AM5: =V5/Team_Defense_Table[[#Totals],[Passing yds/att]]*'Fanduel Export'!Q5 -> 7.8275825 | AN5: =AM5*AK5 -> 209.25737 | AO5: =IFERROR(IF(OR($B5="D",$B5="K"),0,VLOOKUP($P5,Receiving!$C:$T,7,FALSE)/VLOOKUP($P5,Receiving!$C:$T,5,FALSE)),0)*$AJ5 -> 0 | AP5: =SUMIF($J:$J,$J5,AO:AO) -> 19.229762 | AQ5: =AO5/AP5*AH5 -> 0 | AR5: =Y5*AJ5 -> 0 | AS5: =IFERROR(AR5/AO5*AQ5,0) -> 0 | AT5: =AA5/Team_Defense_Table[[#Totals],[Yards per completion]]*'Fanduel Export'!S5 -> 0 | AU5: =AR5*AT5 -> 0 | AV5: =AD5*AJ5 -> 11.733333 | AW5: =SUMIF($J:$J,$J5,AV:AV) -> 27.742262 | AX5: =IFERROR(AV5/AW5*AI5,0) -> 21.367025 | AY5: =AF5/Team_Defense_Table[[#Totals],[Rushing Y/A]]*R5 -> 8 | AZ5: =AY5*AV5 -> 93.866667 | BA5: =AN5/25+AU5/10+AZ5/10+AR5*0.5 -> 17.756962 | BB5: =BA5/(H5/1000) -> 1.8890385 | BC5: =AO5/(H5/1000) -> 0 | BD5: =D5 -> Lamar Jackson | BE5: =H5 -> 9400 | BF5: =B5 -> QB
A6: 47691-28573 | B6: WR | C6: Michael | D6: Michael Thomas | E6: Thomas | F6: 18.75625 | G6: 16 | H6: 8800 | I6: TB@NO | J6: NO | K6: TB | O6: =D6 -> Michael Thomas | P6: =IFERROR(VLOOKUP(O:O,'Name Bridge'!A:B,2,FALSE),O:O) -> Michael Thomas | Q6: =VLOOKUP($K6,'Defensive Stats'!$AC:$AH,2,FALSE) -> 6.5090361 | R6: =VLOOKUP($K6,'Defensive Stats'!$AC:$AH,4,FALSE) -> 3.2624309 | S6: =VLOOKUP($K6,'Defensive Stats'!$AC:$AH,6,FALSE) -> 10.593137 | T6: =IFERROR(VLOOKUP($P6,Passing!$C:$AF,9,FALSE)/VLOOKUP($P6,Passing!$C:$AF,5,FALSE),0) -> 0 | U6: =IFERROR(VLOOKUP($P6,Passing!$C:$AF,11,FALSE)/VLOOKUP($P6,Passing!$C:$AF,5,FALSE),0) -> 0 | V6: =IFERROR(VLOOKUP($P6,Passing!$C:$AF,18,FALSE),0) -> 0 | W6: =IFERROR(VLOOKUP($P6,Passing!$C:$AF,12,FALSE)/VLOOKUP($P6,Passing!$C:$AF,5,FALSE),0) -> 0 | X6: =IFERROR(IF(OR($B6="D",$B6="K"),0,VLOOKUP($P6,Receiving!$C:$T,7,FALSE)/VLOOKUP($P6,Receiving!$C:$T,5,FALSE)),0)*$AJ6 -> 11.5625 | Y6: =IFERROR(VLOOKUP($P6,Receiving!$C:$T,8,FALSE)/VLOOKUP($P6,Receiving!$C:$T,5,FALSE),0) -> 9.3125 | Z6: =IFERROR(VLOOKUP($P6,Receiving!$C:$T,10,FALSE)/VLOOKUP($P6,Receiving!$C:$T,5,FALSE),0) -> 107.8125 | AA6: =IFERROR(VLOOKUP($P6,Receiving!$C:$T,11,FALSE),0) -> 11.6 | AB6: =IFERROR(VLOOKUP($P6,Receiving!$C:$T,14,FALSE),0) -> 49 | AC6: =IFERROR(VLOOKUP($P6,Receiving!$C:$T,11,FALSE)/VLOOKUP($P6,Receiving!$C:$T,5,FALSE),0) -> 0.725 | AD6: =IFERROR(VLOOKUP($P6,Rushing!$C:$P,7,FALSE)/VLOOKUP($P6,Rushing!$C:$P,5,FALSE),0) -> 0.0625 | AE6: =IFERROR(VLOOKUP($P6,Rushing!$C:$P,8,FALSE)/VLOOKUP($P6,Rushing!$C:$P,5,FALSE),0) -> -0.5625 | AF6: =IFERROR(VLOOKUP($P6,Rushing!$C:$P,12,FALSE),0) -> -9.0 | AG6: =IFERROR(VLOOKUP($P6,Rushing!$C:$P,9,FALSE)/VLOOKUP($P6,Rushing!$C:$P,5,FALSE),0) -> 0 | AH6: =VLOOKUP($J6,'Vegas Odds'!$B:$S,18,FALSE) -> 41.698086 | AI6: =VLOOKUP($J6,'Vegas Odds'!$B:$S,17,FALSE) -> 21.901914 | AJ6: 1 | AK6: =T6*AJ6 -> 0 | AL6: =IF(AND(AJ6=1,B6="QB"),AH6,0) -> 0 | AM6: =V6/Team_Defense_Table[[#Totals],[Passing yds/att]]*'Fanduel Export'!Q6 -> 0 | AN6: =AM6*AK6 -> 0 | AO6: =IFERROR(IF(OR($B6="D",$B6="K"),0,VLOOKUP($P6,Receiving!$C:$T,7,FALSE)/VLOOKUP($P6,Receiving!$C:$T,5,FALSE)),0)*$AJ6 -> 11.5625 | AP6: =SUMIF($J:$J,$J6,AO:AO) -> 40.582776 | AQ6: =AO6/AP6*AH6 -> 11.880265 | AR6: =Y6*AJ6 -> 9.3125 | AS6: =IFERROR(AR6/AO6*AQ6,0) -> 9.5684292 | AT6: =AA6/Team_Defense_Table[[#Totals],[Yards per completion]]*'Fanduel Export'!S6 -> 11.572273 | AU6: =AR6*AT6 -> 107.76679 | AV6: =AD6*AJ6 -> 0.0625 | AW6: =SUMIF($J:$J,$J6,AV:AV) -> 30.380682 | AX6: =IFERROR(AV6/AW6*AI6,0) -> 0.045057239 | AY6: =AF6/Team_Defense_Table[[#Totals],[Rushing Y/A]]*R6 -> -6.8085515 | AZ6: =AY6*AV6 -> -0.42553447 | BA6: =AN6/25+AU6/10+AZ6/10+AR6*0.5 -> 15.390376 | BB6: =BA6/(H6/1000) -> 1.7489063 | BC6: =AO6/(H6/1000) -> 1.3139205 | BD6: =D6 -> Michael Thomas | BE6: =H6 -> 8800 | BF6: =B6 -> WR
A7: 47691-54140 | B7: RB | C7: Dalvin | D7: Dalvin Cook | E7: Cook | F7: 18.992857 | G7: 14 | H7: 8700 | I7: GB@MIN | J7: MIN | K7: GB | O7: =D7 -> Dalvin Cook | P7: =IFERROR(VLOOKUP(O:O,'Name Bridge'!A:B,2,FALSE),O:O) -> Dalvin Cook | Q7: =VLOOKUP($K7,'Defensive Stats'!$AC:$AH,2,FALSE) -> 6.8150183 | R7: =VLOOKUP($K7,'Defensive Stats'!$AC:$AH,4,FALSE) -> 4.6739659 | S7: =VLOOKUP($K7,'Defensive Stats'!$AC:$AH,6,FALSE) -> 11.41411 | T7: =IFERROR(VLOOKUP($P7,Passing!$C:$AF,9,FALSE)/VLOOKUP($P7,Passing!$C:$AF,5,FALSE),0) -> 0 | U7: =IFERROR(VLOOKUP($P7,Passing!$C:$AF,11,FALSE)/VLOOKUP($P7,Passing!$C:$AF,5,FALSE),0) -> 0 | V7: =IFERROR(VLOOKUP($P7,Passing!$C:$AF,18,FALSE),0) -> 0 | W7: =IFERROR(VLOOKUP($P7,Passing!$C:$AF,12,FALSE)/VLOOKUP($P7,Passing!$C:$AF,5,FALSE),0) -> 0 | X7: =IFERROR(IF(OR($B7="D",$B7="K"),0,VLOOKUP($P7,Receiving!$C:$T,7,FALSE)/VLOOKUP($P7,Receiving!$C:$T,5,FALSE)),0)*$AJ7 -> 4.5 | Y7: =IFERROR(VLOOKUP($P7,Receiving!$C:$T,8,FALSE)/VLOOKUP($P7,Receiving!$C:$T,5,FALSE),0) -> 3.7857143 | Z7: =IFERROR(VLOOKUP($P7,Receiving!$C:$T,10,FALSE)/VLOOKUP($P7,Receiving!$C:$T,5,FALSE),0) -> 37.071429 | AA7: =IFERROR(VLOOKUP($P7,Receiving!$C:$T,11,FALSE),0) -> 9.8 | AB7: =IFERROR(VLOOKUP($P7,Receiving!$C:$T,14,FALSE),0) -> 31 | AC7: =IFERROR(VLOOKUP($P7,Receiving!$C:$T,11,FALSE)/VLOOKUP($P7,Receiving!$C:$T,5,FALSE),0) -> 0.7 | AD7: =IFERROR(VLOOKUP($P7,Rushing!$C:$P,7,FALSE)/VLOOKUP($P7,Rushing!$C:$P,5,FALSE),0) -> 17.857143 | AE7: =IFERROR(VLOOKUP($P7,Rushing!$C:$P,8,FALSE)/VLOOKUP($P7,Rushing!$C:$P,5,FALSE),0) -> 81.071429 | AF7: =IFERROR(VLOOKUP($P7,Rushing!$C:$P,12,FALSE),0) -> 4.5 | AG7: =IFERROR(VLOOKUP($P7,Rushing!$C:$P,9,FALSE)/VLOOKUP($P7,Rushing!$C:$P,5,FALSE),0) -> 0.92857143 | AH7: =VLOOKUP($J7,'Vegas Odds'!$B:$S,18,FALSE) -> 24.965897 | AI7: =VLOOKUP($J7,'Vegas Odds'!$B:$S,17,FALSE) -> 34.134103 | AJ7: 1 | AK7: =T7*AJ7 -> 0 | AL7: =IF(AND(AJ7=1,B7="QB"),AH7,0) -> 0 | AM7: =V7/Team_Defense_Table[[#Totals],[Passing yds/att]]*'Fanduel Export'!Q7 -> 0 | AN7: =AM7*AK7 -> 0 | AO7: =IFERROR(IF(OR($B7="D",$B7="K"),0,VLOOKUP($P7,Receiving!$C:$T,7,FALSE)/VLOOKUP($P7,Receiving!$C:$T,5,FALSE)),0)*$AJ7 -> 4.5 | AP7: =SUMIF($J:$J,$J7,AO:AO) -> 26.827244 | AQ7: =AO7/AP7*AH7 -> 4.1877778 | AR7: =Y7*AJ7 -> 3.7857143 | AS7: =IFERROR(AR7/AO7*AQ7,0) -> 3.5230512 | AT7: =AA7/Team_Defense_Table[[#Totals],[Yards per completion]]*'Fanduel Export'!S7 -> 10.534264 | AU7: =AR7*AT7 -> 39.879716 | AV7: =AD7*AJ7 -> 17.857143 | AW7: =SUMIF($J:$J,$J7,AV:AV) -> 37.682784 | AX7: =IFERROR(AV7/AW7*AI7,0) -> 16.175492 | AY7: =AF7/Team_Defense_Table[[#Totals],[Rushing Y/A]]*R7 -> 4.8771818 | AZ7: =AY7*AV7 -> 87.092533 | BA7: =AN7/25+AU7/10+AZ7/10+AR7*0.5 -> 14.590082 | BB7: =BA7/(H7/1000) -> 1.6770209 | BC7: =AO7/(H7/1000) -> 0.51724138 | BD7: =D7 -> Dalvin Cook | BE7: =H7 -> 8700 | BF7: =B7 -> RB
A8: 47691-22015 | B8: QB | C8: Russell | D8: Russell Wilson | E8: Wilson | F8: 20.85 | G8: 16 | H8: 8400 | I8: SEA@ATL | J8: SEA | K8: ATL | O8: =D8 -> Russell Wilson | P8: =IFERROR(VLOOKUP(O:O,'Name Bridge'!A:B,2,FALSE),O:O) -> Russell Wilson | Q8: =VLOOKUP($K8,'Defensive Stats'!$AC:$AH,2,FALSE) -> 7.3097015 | R8: =VLOOKUP($K8,'Defensive Stats'!$AC:$AH,4,FALSE) -> 4.216152 | S8: =VLOOKUP($K8,'Defensive Stats'!$AC:$AH,6,FALSE) -> 11.162393 | T8: =IFERROR(VLOOKUP($P8,Passing!$C:$AF,9,FALSE)/VLOOKUP($P8,Passing!$C:$AF,5,FALSE),0) -> 32.25 | U8: =IFERROR(VLOOKUP($P8,Passing!$C:$AF,11,FALSE)/VLOOKUP($P8,Passing!$C:$AF,5,FALSE),0) -> 256.875 | V8: =IFERROR(VLOOKUP($P8,Passing!$C:$AF,18,FALSE),0) -> 8.0 | W8: =IFERROR(VLOOKUP($P8,Passing!$C:$AF,12,FALSE)/VLOOKUP($P8,Passing!$C:$AF,5,FALSE),0) -> 1.9375 | X8: =IFERROR(IF(OR($B8="D",$B8="K"),0,VLOOKUP($P8,Receiving!$C:$T,7,FALSE)/VLOOKUP($P8,Receiving!$C:$T,5,FALSE)),0)*$AJ8 -> 0 | Y8: =IFERROR(VLOOKUP($P8,Receiving!$C:$T,8,FALSE)/VLOOKUP($P8,Receiving!$C:$T,5,FALSE),0) -> 0 | Z8: =IFERROR(VLOOKUP($P8,Receiving!$C:$T,10,FALSE)/VLOOKUP($P8,Receiving!$C:$T,5,FALSE),0) -> 0 | AA8: =IFERROR(VLOOKUP($P8,Receiving!$C:$T,11,FALSE),0) -> 0 | AB8: =IFERROR(VLOOKUP($P8,Receiving!$C:$T,14,FALSE),0) -> 0 | AC8: =IFERROR(VLOOKUP($P8,Receiving!$C:$T,11,FALSE)/VLOOKUP($P8,Receiving!$C:$T,5,FALSE),0) -> 0 | AD8: =IFERROR(VLOOKUP($P8,Rushing!$C:$P,7,FALSE)/VLOOKUP($P8,Rushing!$C:$P,5,FALSE),0) -> 4.6875 | AE8: =IFERROR(VLOOKUP($P8,Rushing!$C:$P,8,FALSE)/VLOOKUP($P8,Rushing!$C:$P,5,FALSE),0) -> 21.375 | AF8: =IFERROR(VLOOKUP($P8,Rushing!$C:$P,12,FALSE),0) -> 4.6 | AG8: =IFERROR(VLOOKUP($P8,Rushing!$C:$P,9,FALSE)/VLOOKUP($P8,Rushing!$C:$P,5,FALSE),0) -> 0.1875 | AH8: =VLOOKUP($J8,'Vegas Odds'!$B:$S,18,FALSE) -> 34.284944 | AI8: =VLOOKUP($J8,'Vegas Odds'!$B:$S,17,FALSE) -> 30.315056 | AJ8: 1 | AK8: =T8*AJ8 -> 32.25 | AL8: =IF(AND(AJ8=1,B8="QB"),AH8,0) -> 34.284944 | AM8: =V8/Team_Defense_Table[[#Totals],[Passing yds/att]]*'Fanduel Export'!Q8 -> 8.6758207 | AN8: =AM8*AK8 -> 279.79522 | AO8: =IFERROR(IF(OR($B8="D",$B8="K"),0,VLOOKUP($P8,Receiving!$C:$T,7,FALSE)/VLOOKUP($P8,Receiving!$C:$T,5,FALSE)),0)*$AJ8 -> 0 | AP8: =SUMIF($J:$J,$J8,AO:AO) -> 34.263041 | AQ8: =AO8/AP8*AH8 -> 0 | AR8: =Y8*AJ8 -> 0 | AS8: =IFERROR(AR8/AO8*AQ8,0) -> 0 | AT8: =AA8/Team_Defense_Table[[#Totals],[Yards per completion]]*'Fanduel Export'!S8 -> 0 | AU8: =AR8*AT8 -> 0 | AV8: =AD8*AJ8 -> 4.6875 | AW8: =SUMIF($J:$J,$J8,AV:AV) -> 46.789286 | AX8: =IFERROR(AV8/AW8*AI8,0) -> 3.0370591 | AY8: =AF8/Team_Defense_Table[[#Totals],[Rushing Y/A]]*R8 -> 4.4972288 | AZ8: =AY8*AV8 -> 21.08076 | BA8: =AN8/25+AU8/10+AZ8/10+AR8*0.5 -> 13.299885 | BB8: =BA8/(H8/1000) -> 1.5833196 | BC8: =AO8/(H8/1000) -> 0 | BD8: =D8 -> Russell Wilson | BE8: =H8 -> 8400 | BF8: =B8 -> QB
A9: 47691-42104 | B9: RB | C9: Alvin | D9: Alvin Kamara | E9: Kamara | F9: 14.858572 | G9: 14 | H9: 8300 | I9: TB@NO | J9: NO | K9: TB | O9: =D9 -> Alvin Kamara | P9: =IFERROR(VLOOKUP(O:O,'Name Bridge'!A:B,2,FALSE),O:O) -> Alvin Kamara | Q9: =VLOOKUP($K9,'Defensive Stats'!$AC:$AH,2,FALSE) -> 6.5090361 | R9: =VLOOKUP($K9,'Defensive Stats'!$AC:$AH,4,FALSE) -> 3.2624309 | S9: =VLOOKUP($K9,'Defensive Stats'!$AC:$AH,6,FALSE) -> 10.593137 | T9: =IFERROR(VLOOKUP($P9,Passing!$C:$AF,9,FALSE)/VLOOKUP($P9,Passing!$C:$AF,5,FALSE),0) -> 0.071428571 | U9: =IFERROR(VLOOKUP($P9,Passing!$C:$AF,11,FALSE)/VLOOKUP($P9,Passing!$C:$AF,5,FALSE),0) -> 0.92857143 | V9: =IFERROR(VLOOKUP($P9,Passing!$C:$AF,18,FALSE),0) -> 13.0 | W9: =IFERROR(VLOOKUP($P9,Passing!$C:$AF,12,FALSE)/VLOOKUP($P9,Passing!$C:$AF,5,FALSE),0) -> 0 | X9: =IFERROR(IF(OR($B9="D",$B9="K"),0,VLOOKUP($P9,Receiving!$C:$T,7,FALSE)/VLOOKUP($P9,Receiving!$C:$T,5,FALSE)),0)*$AJ9 -> 6.9285714 | Y9: =IFERROR(VLOOKUP($P9,Receiving!$C:$T,8,FALSE)/VLOOKUP($P9,Receiving!$C:$T,5,FALSE),0) -> 5.7857143 | Z9: =IFERROR(VLOOKUP($P9,Receiving!$C:$T,10,FALSE)/VLOOKUP($P9,Receiving!$C:$T,5,FALSE),0) -> 38.071429 | AA9: =IFERROR(VLOOKUP($P9,Receiving!$C:$T,11,FALSE),0) -> 6.6 | AB9: =IFERROR(VLOOKUP($P9,Receiving!$C:$T,14,FALSE),0) -> 41 | AC9: =IFERROR(VLOOKUP($P9,Receiving!$C:$T,11,FALSE)/VLOOKUP($P9,Receiving!$C:$T,5,FALSE),0) -> 0.47142857 | AD9: =IFERROR(VLOOKUP($P9,Rushing!$C:$P,7,FALSE)/VLOOKUP($P9,Rushing!$C:$P,5,FALSE),0) -> 12.214286 | AE9: =IFERROR(VLOOKUP($P9,Rushing!$C:$P,8,FALSE)/VLOOKUP($P9,Rushing!$C:$P,5,FALSE),0) -> 56.928571 | AF9: =IFERROR(VLOOKUP($P9,Rushing!$C:$P,12,FALSE),0) -> 4.7 | AG9: =IFERROR(VLOOKUP($P9,Rushing!$C:$P,9,FALSE)/VLOOKUP($P9,Rushing!$C:$P,5,FALSE),0) -> 0.35714286 | AH9: =VLOOKUP($J9,'Vegas Odds'!$B:$S,18,FALSE) -> 41.698086 | AI9: =VLOOKUP($J9,'Vegas Odds'!$B:$S,17,FALSE) -> 21.901914 | AJ9: 1 | AK9: =T9*AJ9 -> 0.071428571 | AL9: =IF(AND(AJ9=1,B9="QB"),AH9,0) -> 0 | AM9: =V9/Team_Defense_Table[[#Totals],[Passing yds/att]]*'Fanduel Export'!Q9 -> 12.553967 | AN9: =AM9*AK9 -> 0.89671191 | AO9: =IFERROR(IF(OR($B9="D",$B9="K"),0,VLOOKUP($P9,Receiving!$C:$T,7,FALSE)/VLOOKUP($P9,Receiving!$C:$T,5,FALSE)),0)*$AJ9 -> 6.9285714 | AP9: =SUMIF($J:$J,$J9,AO:AO) -> 40.582776 | AQ9: =AO9/AP9*AH9 -> 7.1189848 | AR9: =Y9*AJ9 -> 5.7857143 | AS9: =IFERROR(AR9/AO9*AQ9,0) -> 5.9447192 | AT9: =AA9/Team_Defense_Table[[#Totals],[Yards per completion]]*'Fanduel Export'!S9 -> 6.5842241 | AU9: =AR9*AT9 -> 38.09444 | AV9: =AD9*AJ9 -> 12.214286 | AW9: =SUMIF($J:$J,$J9,AV:AV) -> 30.380682 | AX9: =IFERROR(AV9/AW9*AI9,0) -> 8.8054718 | AY9: =AF9/Team_Defense_Table[[#Totals],[Rushing Y/A]]*R9 -> 3.5555769 | AZ9: =AY9*AV9 -> 43.428832 | BA9: =AN9/25+AU9/10+AZ9/10+AR9*0.5 -> 11.081053 | BB9: =BA9/(H9/1000) -> 1.3350666 | BC9: =AO9/(H9/1000) -> 0.83476764 | BD9: =D9 -> Alvin Kamara | BE9: =H9 -> 8300 | BF9: =B9 -> RB
